2025-02-22 22:06:04 - app - INFO - Логирование успешно настроено
2025-02-22 22:06:05 - middleware.error_handler - INFO - Входящий запрос: GET http://127.0.0.1:8000/docs
2025-02-22 22:06:05 - middleware.error_handler - INFO - Исходящий ответ: 200
2025-02-22 22:06:05 - middleware.error_handler - INFO - Входящий запрос: GET http://127.0.0.1:8000/openapi.json
2025-02-22 22:06:05 - middleware.error_handler - INFO - Исходящий ответ: 200
2025-02-22 22:06:39 - middleware.error_handler - INFO - Входящий запрос: GET http://127.0.0.1:8000/api/auth/test-logging
2025-02-22 22:06:39 - api.auth.router - INFO - Это info сообщение
2025-02-22 22:06:39 - api.auth.router - WARNING - Это warning сообщение
2025-02-22 22:06:39 - api.auth.router - ERROR - Это error сообщение: Тестовая ошибка
Traceback (most recent call last):
  File "C:\Users\sslinnn\Desktop\PartyFinder\api\auth\router.py", line 90, in test_logging
    raise ValueError("Тестовая ошибка")
ValueError: Тестовая ошибка
2025-02-22 22:06:39 - middleware.error_handler - INFO - Исходящий ответ: 200
2025-02-22 22:07:37 - app - INFO - Логирование успешно настроено
2025-02-22 22:08:39 - middleware.error_handler - INFO - Входящий запрос: POST http://localhost:8000/api/auth/login
2025-02-22 22:08:39 - sqlalchemy.engine.Engine - INFO - select pg_catalog.version()
2025-02-22 22:08:39 - sqlalchemy.engine.Engine - INFO - [raw sql] ()
2025-02-22 22:08:39 - sqlalchemy.engine.Engine - INFO - select current_schema()
2025-02-22 22:08:39 - sqlalchemy.engine.Engine - INFO - [raw sql] ()
2025-02-22 22:08:39 - sqlalchemy.engine.Engine - INFO - show standard_conforming_strings
2025-02-22 22:08:39 - sqlalchemy.engine.Engine - INFO - [raw sql] ()
2025-02-22 22:08:39 - sqlalchemy.engine.Engine - INFO - BEGIN (implicit)
2025-02-22 22:08:39 - sqlalchemy.engine.Engine - INFO - SELECT users.id, users.username, users.password, users.email, users.email_confirmed, users.is_active, users.is_superuser, users.first_name, users.last_name, users.created_at, users.updated_at 
FROM users 
WHERE users.email = $1::VARCHAR
2025-02-22 22:08:39 - sqlalchemy.engine.Engine - INFO - [generated in 0.00282s] ('awdsdwa@mail.ru',)
2025-02-22 22:08:39 - sqlalchemy.engine.Engine - INFO - ROLLBACK
2025-02-22 22:08:39 - middleware.error_handler - INFO - Исходящий ответ: 400
2025-02-22 22:09:37 - app - INFO - Логирование успешно настроено
2025-02-22 22:09:39 - app - INFO - Логирование успешно настроено
2025-02-22 22:09:45 - app - INFO - Логирование успешно настроено
2025-02-22 22:09:46 - middleware.error_handler - INFO - Входящий запрос: POST http://localhost:8000/api/auth/login
2025-02-22 22:09:46 - middleware.error_handler - INFO - Исходящий ответ: 400
2025-02-22 22:13:05 - app - INFO - Логирование успешно настроено
2025-02-22 22:13:07 - app - INFO - Логирование успешно настроено
2025-02-22 22:13:16 - app - INFO - Логирование успешно настроено
2025-02-22 22:13:19 - middleware.error_handler - INFO - Входящий запрос: POST http://localhost:8000/api/auth/login
2025-02-22 22:13:19 - api.auth.router - INFO - Попытка входа пользователя: awdsdwa@mail.ru
2025-02-22 22:13:19 - middleware.error_handler - INFO - Исходящий ответ: 400
2025-02-22 22:13:31 - middleware.error_handler - INFO - Входящий запрос: POST http://localhost:8000/api/auth/login
2025-02-22 22:13:31 - api.auth.router - INFO - Попытка входа пользователя: morison1991@mail.ru
2025-02-22 22:13:32 - middleware.error_handler - INFO - Исходящий ответ: 200
2025-02-22 22:13:32 - middleware.error_handler - INFO - Входящий запрос: GET http://localhost:8000/api/users/me
2025-02-22 22:13:32 - middleware.error_handler - ERROR - Необработанное исключение: 'NoneType' object has no attribute 'rsplit'
Traceback (most recent call last):
  File "C:\Users\sslinnn\Desktop\PartyFinder\.venv\Lib\site-packages\anyio\streams\memory.py", line 111, in receive
    return self.receive_nowait()
           ~~~~~~~~~~~~~~~~~~~^^
  File "C:\Users\sslinnn\Desktop\PartyFinder\.venv\Lib\site-packages\anyio\streams\memory.py", line 106, in receive_nowait
    raise WouldBlock
anyio.WouldBlock

During handling of the above exception, another exception occurred:

Traceback (most recent call last):
  File "C:\Users\sslinnn\Desktop\PartyFinder\.venv\Lib\site-packages\anyio\streams\memory.py", line 124, in receive
    return receiver.item
           ^^^^^^^^^^^^^
AttributeError: 'MemoryObjectItemReceiver' object has no attribute 'item'

During handling of the above exception, another exception occurred:

Traceback (most recent call last):
  File "C:\Users\sslinnn\Desktop\PartyFinder\.venv\Lib\site-packages\starlette\middleware\base.py", line 157, in call_next
    message = await recv_stream.receive()
              ^^^^^^^^^^^^^^^^^^^^^^^^^^^
  File "C:\Users\sslinnn\Desktop\PartyFinder\.venv\Lib\site-packages\anyio\streams\memory.py", line 126, in receive
    raise EndOfStream
anyio.EndOfStream

During handling of the above exception, another exception occurred:

Traceback (most recent call last):
  File "C:\Users\sslinnn\Desktop\PartyFinder\middleware\error_handler.py", line 12, in error_handler
    response = await call_next(request)
               ^^^^^^^^^^^^^^^^^^^^^^^^
  File "C:\Users\sslinnn\Desktop\PartyFinder\.venv\Lib\site-packages\starlette\middleware\base.py", line 163, in call_next
    raise app_exc
  File "C:\Users\sslinnn\Desktop\PartyFinder\.venv\Lib\site-packages\starlette\middleware\base.py", line 149, in coro
    await self.app(scope, receive_or_disconnect, send_no_error)
  File "C:\Users\sslinnn\Desktop\PartyFinder\.venv\Lib\site-packages\starlette\middleware\exceptions.py", line 62, in __call__
    await wrap_app_handling_exceptions(self.app, conn)(scope, receive, send)
  File "C:\Users\sslinnn\Desktop\PartyFinder\.venv\Lib\site-packages\starlette\_exception_handler.py", line 53, in wrapped_app
    raise exc
  File "C:\Users\sslinnn\Desktop\PartyFinder\.venv\Lib\site-packages\starlette\_exception_handler.py", line 42, in wrapped_app
    await app(scope, receive, sender)
  File "C:\Users\sslinnn\Desktop\PartyFinder\.venv\Lib\site-packages\starlette\routing.py", line 715, in __call__
    await self.middleware_stack(scope, receive, send)
  File "C:\Users\sslinnn\Desktop\PartyFinder\.venv\Lib\site-packages\starlette\routing.py", line 735, in app
    await route.handle(scope, receive, send)
  File "C:\Users\sslinnn\Desktop\PartyFinder\.venv\Lib\site-packages\starlette\routing.py", line 288, in handle
    await self.app(scope, receive, send)
  File "C:\Users\sslinnn\Desktop\PartyFinder\.venv\Lib\site-packages\starlette\routing.py", line 76, in app
    await wrap_app_handling_exceptions(app, request)(scope, receive, send)
  File "C:\Users\sslinnn\Desktop\PartyFinder\.venv\Lib\site-packages\starlette\_exception_handler.py", line 53, in wrapped_app
    raise exc
  File "C:\Users\sslinnn\Desktop\PartyFinder\.venv\Lib\site-packages\starlette\_exception_handler.py", line 42, in wrapped_app
    await app(scope, receive, sender)
  File "C:\Users\sslinnn\Desktop\PartyFinder\.venv\Lib\site-packages\starlette\routing.py", line 73, in app
    response = await f(request)
               ^^^^^^^^^^^^^^^^
  File "C:\Users\sslinnn\Desktop\PartyFinder\.venv\Lib\site-packages\fastapi\routing.py", line 291, in app
    solved_result = await solve_dependencies(
                    ^^^^^^^^^^^^^^^^^^^^^^^^^
    ...<6 lines>...
    )
    ^
  File "C:\Users\sslinnn\Desktop\PartyFinder\.venv\Lib\site-packages\fastapi\dependencies\utils.py", line 638, in solve_dependencies
    solved = await call(**solved_result.values)
             ^^^^^^^^^^^^^^^^^^^^^^^^^^^^^^^^^^
  File "C:\Users\sslinnn\Desktop\PartyFinder\api\users\users_utils.py", line 21, in get_current_user
    payload = decode_access_token(token)
  File "C:\Users\sslinnn\Desktop\PartyFinder\utils\JWTUtils.py", line 31, in decode_access_token
    return jwt.decode(
           ~~~~~~~~~~^
        token, auth_data["secret_key"], algorithms=[auth_data["algorithm"]]
        ^^^^^^^^^^^^^^^^^^^^^^^^^^^^^^^^^^^^^^^^^^^^^^^^^^^^^^^^^^^^^^^^^^^
    )
    ^
  File "C:\Users\sslinnn\Desktop\PartyFinder\.venv\Lib\site-packages\jose\jwt.py", line 142, in decode
    payload = jws.verify(token, key, algorithms, verify=verify_signature)
  File "C:\Users\sslinnn\Desktop\PartyFinder\.venv\Lib\site-packages\jose\jws.py", line 70, in verify
    header, payload, signing_input, signature = _load(token)
                                                ~~~~~^^^^^^^
  File "C:\Users\sslinnn\Desktop\PartyFinder\.venv\Lib\site-packages\jose\jws.py", line 176, in _load
    signing_input, crypto_segment = jwt.rsplit(b".", 1)
                                    ^^^^^^^^^^
AttributeError: 'NoneType' object has no attribute 'rsplit'
2025-02-22 22:14:31 - app - INFO - Логирование успешно настроено
2025-02-22 22:14:32 - middleware.error_handler - INFO - Входящий запрос: GET http://127.0.0.1:8000/docs
2025-02-22 22:14:32 - middleware.error_handler - INFO - Исходящий ответ: 200
2025-02-22 22:14:33 - middleware.error_handler - INFO - Входящий запрос: GET http://127.0.0.1:8000/openapi.json
2025-02-22 22:14:33 - middleware.error_handler - INFO - Исходящий ответ: 200
2025-02-22 22:15:26 - middleware.error_handler - INFO - Входящий запрос: POST http://localhost:8000/api/auth/login
2025-02-22 22:15:26 - api.auth.router - INFO - Попытка входа пользователя: morison1991@mail.ru
2025-02-22 22:15:26 - middleware.error_handler - INFO - Исходящий ответ: 200
2025-02-22 22:15:26 - middleware.error_handler - INFO - Входящий запрос: GET http://localhost:8000/api/users/me
2025-02-22 22:15:26 - middleware.error_handler - ERROR - Необработанное исключение: 'NoneType' object has no attribute 'rsplit'
Traceback (most recent call last):
  File "C:\Users\sslinnn\Desktop\PartyFinder\.venv\Lib\site-packages\anyio\streams\memory.py", line 111, in receive
    return self.receive_nowait()
           ~~~~~~~~~~~~~~~~~~~^^
  File "C:\Users\sslinnn\Desktop\PartyFinder\.venv\Lib\site-packages\anyio\streams\memory.py", line 106, in receive_nowait
    raise WouldBlock
anyio.WouldBlock

During handling of the above exception, another exception occurred:

Traceback (most recent call last):
  File "C:\Users\sslinnn\Desktop\PartyFinder\.venv\Lib\site-packages\anyio\streams\memory.py", line 124, in receive
    return receiver.item
           ^^^^^^^^^^^^^
AttributeError: 'MemoryObjectItemReceiver' object has no attribute 'item'

During handling of the above exception, another exception occurred:

Traceback (most recent call last):
  File "C:\Users\sslinnn\Desktop\PartyFinder\.venv\Lib\site-packages\starlette\middleware\base.py", line 157, in call_next
    message = await recv_stream.receive()
              ^^^^^^^^^^^^^^^^^^^^^^^^^^^
  File "C:\Users\sslinnn\Desktop\PartyFinder\.venv\Lib\site-packages\anyio\streams\memory.py", line 126, in receive
    raise EndOfStream
anyio.EndOfStream

During handling of the above exception, another exception occurred:

Traceback (most recent call last):
  File "C:\Users\sslinnn\Desktop\PartyFinder\middleware\error_handler.py", line 12, in error_handler
    response = await call_next(request)
               ^^^^^^^^^^^^^^^^^^^^^^^^
  File "C:\Users\sslinnn\Desktop\PartyFinder\.venv\Lib\site-packages\starlette\middleware\base.py", line 163, in call_next
    raise app_exc
  File "C:\Users\sslinnn\Desktop\PartyFinder\.venv\Lib\site-packages\starlette\middleware\base.py", line 149, in coro
    await self.app(scope, receive_or_disconnect, send_no_error)
  File "C:\Users\sslinnn\Desktop\PartyFinder\.venv\Lib\site-packages\starlette\middleware\exceptions.py", line 62, in __call__
    await wrap_app_handling_exceptions(self.app, conn)(scope, receive, send)
  File "C:\Users\sslinnn\Desktop\PartyFinder\.venv\Lib\site-packages\starlette\_exception_handler.py", line 53, in wrapped_app
    raise exc
  File "C:\Users\sslinnn\Desktop\PartyFinder\.venv\Lib\site-packages\starlette\_exception_handler.py", line 42, in wrapped_app
    await app(scope, receive, sender)
  File "C:\Users\sslinnn\Desktop\PartyFinder\.venv\Lib\site-packages\starlette\routing.py", line 715, in __call__
    await self.middleware_stack(scope, receive, send)
  File "C:\Users\sslinnn\Desktop\PartyFinder\.venv\Lib\site-packages\starlette\routing.py", line 735, in app
    await route.handle(scope, receive, send)
  File "C:\Users\sslinnn\Desktop\PartyFinder\.venv\Lib\site-packages\starlette\routing.py", line 288, in handle
    await self.app(scope, receive, send)
  File "C:\Users\sslinnn\Desktop\PartyFinder\.venv\Lib\site-packages\starlette\routing.py", line 76, in app
    await wrap_app_handling_exceptions(app, request)(scope, receive, send)
  File "C:\Users\sslinnn\Desktop\PartyFinder\.venv\Lib\site-packages\starlette\_exception_handler.py", line 53, in wrapped_app
    raise exc
  File "C:\Users\sslinnn\Desktop\PartyFinder\.venv\Lib\site-packages\starlette\_exception_handler.py", line 42, in wrapped_app
    await app(scope, receive, sender)
  File "C:\Users\sslinnn\Desktop\PartyFinder\.venv\Lib\site-packages\starlette\routing.py", line 73, in app
    response = await f(request)
               ^^^^^^^^^^^^^^^^
  File "C:\Users\sslinnn\Desktop\PartyFinder\.venv\Lib\site-packages\fastapi\routing.py", line 291, in app
    solved_result = await solve_dependencies(
                    ^^^^^^^^^^^^^^^^^^^^^^^^^
    ...<6 lines>...
    )
    ^
  File "C:\Users\sslinnn\Desktop\PartyFinder\.venv\Lib\site-packages\fastapi\dependencies\utils.py", line 638, in solve_dependencies
    solved = await call(**solved_result.values)
             ^^^^^^^^^^^^^^^^^^^^^^^^^^^^^^^^^^
  File "C:\Users\sslinnn\Desktop\PartyFinder\api\users\users_utils.py", line 21, in get_current_user
    payload = decode_access_token(token)
  File "C:\Users\sslinnn\Desktop\PartyFinder\utils\JWTUtils.py", line 31, in decode_access_token
    return jwt.decode(
           ~~~~~~~~~~^
        token, auth_data["secret_key"], algorithms=[auth_data["algorithm"]]
        ^^^^^^^^^^^^^^^^^^^^^^^^^^^^^^^^^^^^^^^^^^^^^^^^^^^^^^^^^^^^^^^^^^^
    )
    ^
  File "C:\Users\sslinnn\Desktop\PartyFinder\.venv\Lib\site-packages\jose\jwt.py", line 142, in decode
    payload = jws.verify(token, key, algorithms, verify=verify_signature)
  File "C:\Users\sslinnn\Desktop\PartyFinder\.venv\Lib\site-packages\jose\jws.py", line 70, in verify
    header, payload, signing_input, signature = _load(token)
                                                ~~~~~^^^^^^^
  File "C:\Users\sslinnn\Desktop\PartyFinder\.venv\Lib\site-packages\jose\jws.py", line 176, in _load
    signing_input, crypto_segment = jwt.rsplit(b".", 1)
                                    ^^^^^^^^^^
AttributeError: 'NoneType' object has no attribute 'rsplit'
2025-02-22 22:24:28 - middleware.error_handler - INFO - Входящий запрос: POST http://localhost:8000/api/auth/login
2025-02-22 22:24:28 - api.auth.router - INFO - Попытка входа пользователя: morison1991@mail.ru
2025-02-22 22:24:28 - middleware.error_handler - INFO - Исходящий ответ: 200
2025-02-22 22:24:28 - middleware.error_handler - INFO - Входящий запрос: GET http://localhost:8000/api/users/me
2025-02-22 22:24:28 - middleware.error_handler - ERROR - Необработанное исключение: 'NoneType' object has no attribute 'rsplit'
Traceback (most recent call last):
  File "C:\Users\sslinnn\Desktop\PartyFinder\.venv\Lib\site-packages\anyio\streams\memory.py", line 111, in receive
    return self.receive_nowait()
           ~~~~~~~~~~~~~~~~~~~^^
  File "C:\Users\sslinnn\Desktop\PartyFinder\.venv\Lib\site-packages\anyio\streams\memory.py", line 106, in receive_nowait
    raise WouldBlock
anyio.WouldBlock

During handling of the above exception, another exception occurred:

Traceback (most recent call last):
  File "C:\Users\sslinnn\Desktop\PartyFinder\.venv\Lib\site-packages\anyio\streams\memory.py", line 124, in receive
    return receiver.item
           ^^^^^^^^^^^^^
AttributeError: 'MemoryObjectItemReceiver' object has no attribute 'item'

During handling of the above exception, another exception occurred:

Traceback (most recent call last):
  File "C:\Users\sslinnn\Desktop\PartyFinder\.venv\Lib\site-packages\starlette\middleware\base.py", line 157, in call_next
    message = await recv_stream.receive()
              ^^^^^^^^^^^^^^^^^^^^^^^^^^^
  File "C:\Users\sslinnn\Desktop\PartyFinder\.venv\Lib\site-packages\anyio\streams\memory.py", line 126, in receive
    raise EndOfStream
anyio.EndOfStream

During handling of the above exception, another exception occurred:

Traceback (most recent call last):
  File "C:\Users\sslinnn\Desktop\PartyFinder\middleware\error_handler.py", line 12, in error_handler
    response = await call_next(request)
               ^^^^^^^^^^^^^^^^^^^^^^^^
  File "C:\Users\sslinnn\Desktop\PartyFinder\.venv\Lib\site-packages\starlette\middleware\base.py", line 163, in call_next
    raise app_exc
  File "C:\Users\sslinnn\Desktop\PartyFinder\.venv\Lib\site-packages\starlette\middleware\base.py", line 149, in coro
    await self.app(scope, receive_or_disconnect, send_no_error)
  File "C:\Users\sslinnn\Desktop\PartyFinder\.venv\Lib\site-packages\starlette\middleware\exceptions.py", line 62, in __call__
    await wrap_app_handling_exceptions(self.app, conn)(scope, receive, send)
  File "C:\Users\sslinnn\Desktop\PartyFinder\.venv\Lib\site-packages\starlette\_exception_handler.py", line 53, in wrapped_app
    raise exc
  File "C:\Users\sslinnn\Desktop\PartyFinder\.venv\Lib\site-packages\starlette\_exception_handler.py", line 42, in wrapped_app
    await app(scope, receive, sender)
  File "C:\Users\sslinnn\Desktop\PartyFinder\.venv\Lib\site-packages\starlette\routing.py", line 715, in __call__
    await self.middleware_stack(scope, receive, send)
  File "C:\Users\sslinnn\Desktop\PartyFinder\.venv\Lib\site-packages\starlette\routing.py", line 735, in app
    await route.handle(scope, receive, send)
  File "C:\Users\sslinnn\Desktop\PartyFinder\.venv\Lib\site-packages\starlette\routing.py", line 288, in handle
    await self.app(scope, receive, send)
  File "C:\Users\sslinnn\Desktop\PartyFinder\.venv\Lib\site-packages\starlette\routing.py", line 76, in app
    await wrap_app_handling_exceptions(app, request)(scope, receive, send)
  File "C:\Users\sslinnn\Desktop\PartyFinder\.venv\Lib\site-packages\starlette\_exception_handler.py", line 53, in wrapped_app
    raise exc
  File "C:\Users\sslinnn\Desktop\PartyFinder\.venv\Lib\site-packages\starlette\_exception_handler.py", line 42, in wrapped_app
    await app(scope, receive, sender)
  File "C:\Users\sslinnn\Desktop\PartyFinder\.venv\Lib\site-packages\starlette\routing.py", line 73, in app
    response = await f(request)
               ^^^^^^^^^^^^^^^^
  File "C:\Users\sslinnn\Desktop\PartyFinder\.venv\Lib\site-packages\fastapi\routing.py", line 291, in app
    solved_result = await solve_dependencies(
                    ^^^^^^^^^^^^^^^^^^^^^^^^^
    ...<6 lines>...
    )
    ^
  File "C:\Users\sslinnn\Desktop\PartyFinder\.venv\Lib\site-packages\fastapi\dependencies\utils.py", line 638, in solve_dependencies
    solved = await call(**solved_result.values)
             ^^^^^^^^^^^^^^^^^^^^^^^^^^^^^^^^^^
  File "C:\Users\sslinnn\Desktop\PartyFinder\api\users\users_utils.py", line 21, in get_current_user
    payload = decode_access_token(token)
  File "C:\Users\sslinnn\Desktop\PartyFinder\utils\JWTUtils.py", line 31, in decode_access_token
    return jwt.decode(
           ~~~~~~~~~~^
        token, auth_data["secret_key"], algorithms=[auth_data["algorithm"]]
        ^^^^^^^^^^^^^^^^^^^^^^^^^^^^^^^^^^^^^^^^^^^^^^^^^^^^^^^^^^^^^^^^^^^
    )
    ^
  File "C:\Users\sslinnn\Desktop\PartyFinder\.venv\Lib\site-packages\jose\jwt.py", line 142, in decode
    payload = jws.verify(token, key, algorithms, verify=verify_signature)
  File "C:\Users\sslinnn\Desktop\PartyFinder\.venv\Lib\site-packages\jose\jws.py", line 70, in verify
    header, payload, signing_input, signature = _load(token)
                                                ~~~~~^^^^^^^
  File "C:\Users\sslinnn\Desktop\PartyFinder\.venv\Lib\site-packages\jose\jws.py", line 176, in _load
    signing_input, crypto_segment = jwt.rsplit(b".", 1)
                                    ^^^^^^^^^^
AttributeError: 'NoneType' object has no attribute 'rsplit'
2025-02-22 22:29:06 - app - INFO - Логирование успешно настроено
2025-02-22 22:29:22 - middleware.error_handler - INFO - Входящий запрос: POST http://localhost:8000/api/auth/login
2025-02-22 22:29:22 - api.auth.router - INFO - Попытка входа пользователя: morison1991@mail.ru
2025-02-22 22:29:22 - middleware.error_handler - INFO - Исходящий ответ: 200
2025-02-22 22:29:22 - middleware.error_handler - INFO - Входящий запрос: GET http://localhost:8000/api/users/me
2025-02-22 22:29:22 - middleware.error_handler - ERROR - Необработанное исключение: 'NoneType' object has no attribute 'rsplit'
Traceback (most recent call last):
  File "C:\Users\sslinnn\Desktop\PartyFinder\.venv\Lib\site-packages\anyio\streams\memory.py", line 111, in receive
    return self.receive_nowait()
           ~~~~~~~~~~~~~~~~~~~^^
  File "C:\Users\sslinnn\Desktop\PartyFinder\.venv\Lib\site-packages\anyio\streams\memory.py", line 106, in receive_nowait
    raise WouldBlock
anyio.WouldBlock

During handling of the above exception, another exception occurred:

Traceback (most recent call last):
  File "C:\Users\sslinnn\Desktop\PartyFinder\.venv\Lib\site-packages\anyio\streams\memory.py", line 124, in receive
    return receiver.item
           ^^^^^^^^^^^^^
AttributeError: 'MemoryObjectItemReceiver' object has no attribute 'item'

During handling of the above exception, another exception occurred:

Traceback (most recent call last):
  File "C:\Users\sslinnn\Desktop\PartyFinder\.venv\Lib\site-packages\starlette\middleware\base.py", line 157, in call_next
    message = await recv_stream.receive()
              ^^^^^^^^^^^^^^^^^^^^^^^^^^^
  File "C:\Users\sslinnn\Desktop\PartyFinder\.venv\Lib\site-packages\anyio\streams\memory.py", line 126, in receive
    raise EndOfStream
anyio.EndOfStream

During handling of the above exception, another exception occurred:

Traceback (most recent call last):
  File "C:\Users\sslinnn\Desktop\PartyFinder\middleware\error_handler.py", line 12, in error_handler
    response = await call_next(request)
               ^^^^^^^^^^^^^^^^^^^^^^^^
  File "C:\Users\sslinnn\Desktop\PartyFinder\.venv\Lib\site-packages\starlette\middleware\base.py", line 163, in call_next
    raise app_exc
  File "C:\Users\sslinnn\Desktop\PartyFinder\.venv\Lib\site-packages\starlette\middleware\base.py", line 149, in coro
    await self.app(scope, receive_or_disconnect, send_no_error)
  File "C:\Users\sslinnn\Desktop\PartyFinder\.venv\Lib\site-packages\starlette\middleware\exceptions.py", line 62, in __call__
    await wrap_app_handling_exceptions(self.app, conn)(scope, receive, send)
  File "C:\Users\sslinnn\Desktop\PartyFinder\.venv\Lib\site-packages\starlette\_exception_handler.py", line 53, in wrapped_app
    raise exc
  File "C:\Users\sslinnn\Desktop\PartyFinder\.venv\Lib\site-packages\starlette\_exception_handler.py", line 42, in wrapped_app
    await app(scope, receive, sender)
  File "C:\Users\sslinnn\Desktop\PartyFinder\.venv\Lib\site-packages\starlette\routing.py", line 715, in __call__
    await self.middleware_stack(scope, receive, send)
  File "C:\Users\sslinnn\Desktop\PartyFinder\.venv\Lib\site-packages\starlette\routing.py", line 735, in app
    await route.handle(scope, receive, send)
  File "C:\Users\sslinnn\Desktop\PartyFinder\.venv\Lib\site-packages\starlette\routing.py", line 288, in handle
    await self.app(scope, receive, send)
  File "C:\Users\sslinnn\Desktop\PartyFinder\.venv\Lib\site-packages\starlette\routing.py", line 76, in app
    await wrap_app_handling_exceptions(app, request)(scope, receive, send)
  File "C:\Users\sslinnn\Desktop\PartyFinder\.venv\Lib\site-packages\starlette\_exception_handler.py", line 53, in wrapped_app
    raise exc
  File "C:\Users\sslinnn\Desktop\PartyFinder\.venv\Lib\site-packages\starlette\_exception_handler.py", line 42, in wrapped_app
    await app(scope, receive, sender)
  File "C:\Users\sslinnn\Desktop\PartyFinder\.venv\Lib\site-packages\starlette\routing.py", line 73, in app
    response = await f(request)
               ^^^^^^^^^^^^^^^^
  File "C:\Users\sslinnn\Desktop\PartyFinder\.venv\Lib\site-packages\fastapi\routing.py", line 291, in app
    solved_result = await solve_dependencies(
                    ^^^^^^^^^^^^^^^^^^^^^^^^^
    ...<6 lines>...
    )
    ^
  File "C:\Users\sslinnn\Desktop\PartyFinder\.venv\Lib\site-packages\fastapi\dependencies\utils.py", line 638, in solve_dependencies
    solved = await call(**solved_result.values)
             ^^^^^^^^^^^^^^^^^^^^^^^^^^^^^^^^^^
  File "C:\Users\sslinnn\Desktop\PartyFinder\api\users\users_utils.py", line 21, in get_current_user
    payload = decode_access_token(token)
  File "C:\Users\sslinnn\Desktop\PartyFinder\utils\JWTUtils.py", line 31, in decode_access_token
    return jwt.decode(
           ~~~~~~~~~~^
        token, auth_data["secret_key"], algorithms=[auth_data["algorithm"]]
        ^^^^^^^^^^^^^^^^^^^^^^^^^^^^^^^^^^^^^^^^^^^^^^^^^^^^^^^^^^^^^^^^^^^
    )
    ^
  File "C:\Users\sslinnn\Desktop\PartyFinder\.venv\Lib\site-packages\jose\jwt.py", line 142, in decode
    payload = jws.verify(token, key, algorithms, verify=verify_signature)
  File "C:\Users\sslinnn\Desktop\PartyFinder\.venv\Lib\site-packages\jose\jws.py", line 70, in verify
    header, payload, signing_input, signature = _load(token)
                                                ~~~~~^^^^^^^
  File "C:\Users\sslinnn\Desktop\PartyFinder\.venv\Lib\site-packages\jose\jws.py", line 176, in _load
    signing_input, crypto_segment = jwt.rsplit(b".", 1)
                                    ^^^^^^^^^^
AttributeError: 'NoneType' object has no attribute 'rsplit'
2025-02-22 22:31:09 - middleware.error_handler - INFO - Входящий запрос: POST http://localhost:8000/api/auth/login
2025-02-22 22:31:09 - api.auth.router - INFO - Попытка входа пользователя: morison1991@mail.ru
2025-02-22 22:31:10 - middleware.error_handler - INFO - Исходящий ответ: 200
2025-02-22 22:31:10 - middleware.error_handler - INFO - Входящий запрос: GET http://localhost:8000/api/users/me
2025-02-22 22:31:10 - middleware.error_handler - ERROR - Необработанное исключение: 'NoneType' object has no attribute 'rsplit'
Traceback (most recent call last):
  File "C:\Users\sslinnn\Desktop\PartyFinder\.venv\Lib\site-packages\anyio\streams\memory.py", line 111, in receive
    return self.receive_nowait()
           ~~~~~~~~~~~~~~~~~~~^^
  File "C:\Users\sslinnn\Desktop\PartyFinder\.venv\Lib\site-packages\anyio\streams\memory.py", line 106, in receive_nowait
    raise WouldBlock
anyio.WouldBlock

During handling of the above exception, another exception occurred:

Traceback (most recent call last):
  File "C:\Users\sslinnn\Desktop\PartyFinder\.venv\Lib\site-packages\anyio\streams\memory.py", line 124, in receive
    return receiver.item
           ^^^^^^^^^^^^^
AttributeError: 'MemoryObjectItemReceiver' object has no attribute 'item'

During handling of the above exception, another exception occurred:

Traceback (most recent call last):
  File "C:\Users\sslinnn\Desktop\PartyFinder\.venv\Lib\site-packages\starlette\middleware\base.py", line 157, in call_next
    message = await recv_stream.receive()
              ^^^^^^^^^^^^^^^^^^^^^^^^^^^
  File "C:\Users\sslinnn\Desktop\PartyFinder\.venv\Lib\site-packages\anyio\streams\memory.py", line 126, in receive
    raise EndOfStream
anyio.EndOfStream

During handling of the above exception, another exception occurred:

Traceback (most recent call last):
  File "C:\Users\sslinnn\Desktop\PartyFinder\middleware\error_handler.py", line 12, in error_handler
    response = await call_next(request)
               ^^^^^^^^^^^^^^^^^^^^^^^^
  File "C:\Users\sslinnn\Desktop\PartyFinder\.venv\Lib\site-packages\starlette\middleware\base.py", line 163, in call_next
    raise app_exc
  File "C:\Users\sslinnn\Desktop\PartyFinder\.venv\Lib\site-packages\starlette\middleware\base.py", line 149, in coro
    await self.app(scope, receive_or_disconnect, send_no_error)
  File "C:\Users\sslinnn\Desktop\PartyFinder\.venv\Lib\site-packages\starlette\middleware\exceptions.py", line 62, in __call__
    await wrap_app_handling_exceptions(self.app, conn)(scope, receive, send)
  File "C:\Users\sslinnn\Desktop\PartyFinder\.venv\Lib\site-packages\starlette\_exception_handler.py", line 53, in wrapped_app
    raise exc
  File "C:\Users\sslinnn\Desktop\PartyFinder\.venv\Lib\site-packages\starlette\_exception_handler.py", line 42, in wrapped_app
    await app(scope, receive, sender)
  File "C:\Users\sslinnn\Desktop\PartyFinder\.venv\Lib\site-packages\starlette\routing.py", line 715, in __call__
    await self.middleware_stack(scope, receive, send)
  File "C:\Users\sslinnn\Desktop\PartyFinder\.venv\Lib\site-packages\starlette\routing.py", line 735, in app
    await route.handle(scope, receive, send)
  File "C:\Users\sslinnn\Desktop\PartyFinder\.venv\Lib\site-packages\starlette\routing.py", line 288, in handle
    await self.app(scope, receive, send)
  File "C:\Users\sslinnn\Desktop\PartyFinder\.venv\Lib\site-packages\starlette\routing.py", line 76, in app
    await wrap_app_handling_exceptions(app, request)(scope, receive, send)
  File "C:\Users\sslinnn\Desktop\PartyFinder\.venv\Lib\site-packages\starlette\_exception_handler.py", line 53, in wrapped_app
    raise exc
  File "C:\Users\sslinnn\Desktop\PartyFinder\.venv\Lib\site-packages\starlette\_exception_handler.py", line 42, in wrapped_app
    await app(scope, receive, sender)
  File "C:\Users\sslinnn\Desktop\PartyFinder\.venv\Lib\site-packages\starlette\routing.py", line 73, in app
    response = await f(request)
               ^^^^^^^^^^^^^^^^
  File "C:\Users\sslinnn\Desktop\PartyFinder\.venv\Lib\site-packages\fastapi\routing.py", line 291, in app
    solved_result = await solve_dependencies(
                    ^^^^^^^^^^^^^^^^^^^^^^^^^
    ...<6 lines>...
    )
    ^
  File "C:\Users\sslinnn\Desktop\PartyFinder\.venv\Lib\site-packages\fastapi\dependencies\utils.py", line 638, in solve_dependencies
    solved = await call(**solved_result.values)
             ^^^^^^^^^^^^^^^^^^^^^^^^^^^^^^^^^^
  File "C:\Users\sslinnn\Desktop\PartyFinder\api\users\users_utils.py", line 21, in get_current_user
    if not token:
              ^^^
  File "C:\Users\sslinnn\Desktop\PartyFinder\utils\JWTUtils.py", line 31, in decode_access_token
    
    auth_data = get_auth_data()
    try:
  File "C:\Users\sslinnn\Desktop\PartyFinder\.venv\Lib\site-packages\jose\jwt.py", line 142, in decode
    payload = jws.verify(token, key, algorithms, verify=verify_signature)
  File "C:\Users\sslinnn\Desktop\PartyFinder\.venv\Lib\site-packages\jose\jws.py", line 70, in verify
    header, payload, signing_input, signature = _load(token)
                                                ~~~~~^^^^^^^
  File "C:\Users\sslinnn\Desktop\PartyFinder\.venv\Lib\site-packages\jose\jws.py", line 176, in _load
    signing_input, crypto_segment = jwt.rsplit(b".", 1)
                                    ^^^^^^^^^^
AttributeError: 'NoneType' object has no attribute 'rsplit'
2025-02-22 22:31:19 - middleware.error_handler - INFO - Входящий запрос: POST http://localhost:8000/api/auth/login
2025-02-22 22:31:19 - api.auth.router - INFO - Попытка входа пользователя: morison1991@mail.ru
2025-02-22 22:31:20 - middleware.error_handler - INFO - Исходящий ответ: 200
2025-02-22 22:31:20 - middleware.error_handler - INFO - Входящий запрос: GET http://localhost:8000/api/users/me
2025-02-22 22:31:20 - middleware.error_handler - ERROR - Необработанное исключение: 'NoneType' object has no attribute 'rsplit'
Traceback (most recent call last):
  File "C:\Users\sslinnn\Desktop\PartyFinder\.venv\Lib\site-packages\anyio\streams\memory.py", line 111, in receive
    return self.receive_nowait()
           ~~~~~~~~~~~~~~~~~~~^^
  File "C:\Users\sslinnn\Desktop\PartyFinder\.venv\Lib\site-packages\anyio\streams\memory.py", line 106, in receive_nowait
    raise WouldBlock
anyio.WouldBlock

During handling of the above exception, another exception occurred:

Traceback (most recent call last):
  File "C:\Users\sslinnn\Desktop\PartyFinder\.venv\Lib\site-packages\anyio\streams\memory.py", line 124, in receive
    return receiver.item
           ^^^^^^^^^^^^^
AttributeError: 'MemoryObjectItemReceiver' object has no attribute 'item'

During handling of the above exception, another exception occurred:

Traceback (most recent call last):
  File "C:\Users\sslinnn\Desktop\PartyFinder\.venv\Lib\site-packages\starlette\middleware\base.py", line 157, in call_next
    message = await recv_stream.receive()
              ^^^^^^^^^^^^^^^^^^^^^^^^^^^
  File "C:\Users\sslinnn\Desktop\PartyFinder\.venv\Lib\site-packages\anyio\streams\memory.py", line 126, in receive
    raise EndOfStream
anyio.EndOfStream

During handling of the above exception, another exception occurred:

Traceback (most recent call last):
  File "C:\Users\sslinnn\Desktop\PartyFinder\middleware\error_handler.py", line 12, in error_handler
    response = await call_next(request)
               ^^^^^^^^^^^^^^^^^^^^^^^^
  File "C:\Users\sslinnn\Desktop\PartyFinder\.venv\Lib\site-packages\starlette\middleware\base.py", line 163, in call_next
    raise app_exc
  File "C:\Users\sslinnn\Desktop\PartyFinder\.venv\Lib\site-packages\starlette\middleware\base.py", line 149, in coro
    await self.app(scope, receive_or_disconnect, send_no_error)
  File "C:\Users\sslinnn\Desktop\PartyFinder\.venv\Lib\site-packages\starlette\middleware\exceptions.py", line 62, in __call__
    await wrap_app_handling_exceptions(self.app, conn)(scope, receive, send)
  File "C:\Users\sslinnn\Desktop\PartyFinder\.venv\Lib\site-packages\starlette\_exception_handler.py", line 53, in wrapped_app
    raise exc
  File "C:\Users\sslinnn\Desktop\PartyFinder\.venv\Lib\site-packages\starlette\_exception_handler.py", line 42, in wrapped_app
    await app(scope, receive, sender)
  File "C:\Users\sslinnn\Desktop\PartyFinder\.venv\Lib\site-packages\starlette\routing.py", line 715, in __call__
    await self.middleware_stack(scope, receive, send)
  File "C:\Users\sslinnn\Desktop\PartyFinder\.venv\Lib\site-packages\starlette\routing.py", line 735, in app
    await route.handle(scope, receive, send)
  File "C:\Users\sslinnn\Desktop\PartyFinder\.venv\Lib\site-packages\starlette\routing.py", line 288, in handle
    await self.app(scope, receive, send)
  File "C:\Users\sslinnn\Desktop\PartyFinder\.venv\Lib\site-packages\starlette\routing.py", line 76, in app
    await wrap_app_handling_exceptions(app, request)(scope, receive, send)
  File "C:\Users\sslinnn\Desktop\PartyFinder\.venv\Lib\site-packages\starlette\_exception_handler.py", line 53, in wrapped_app
    raise exc
  File "C:\Users\sslinnn\Desktop\PartyFinder\.venv\Lib\site-packages\starlette\_exception_handler.py", line 42, in wrapped_app
    await app(scope, receive, sender)
  File "C:\Users\sslinnn\Desktop\PartyFinder\.venv\Lib\site-packages\starlette\routing.py", line 73, in app
    response = await f(request)
               ^^^^^^^^^^^^^^^^
  File "C:\Users\sslinnn\Desktop\PartyFinder\.venv\Lib\site-packages\fastapi\routing.py", line 291, in app
    solved_result = await solve_dependencies(
                    ^^^^^^^^^^^^^^^^^^^^^^^^^
    ...<6 lines>...
    )
    ^
  File "C:\Users\sslinnn\Desktop\PartyFinder\.venv\Lib\site-packages\fastapi\dependencies\utils.py", line 638, in solve_dependencies
    solved = await call(**solved_result.values)
             ^^^^^^^^^^^^^^^^^^^^^^^^^^^^^^^^^^
  File "C:\Users\sslinnn\Desktop\PartyFinder\api\users\users_utils.py", line 21, in get_current_user
    if not token:
              ^^^
  File "C:\Users\sslinnn\Desktop\PartyFinder\utils\JWTUtils.py", line 31, in decode_access_token
    
    auth_data = get_auth_data()
    try:
  File "C:\Users\sslinnn\Desktop\PartyFinder\.venv\Lib\site-packages\jose\jwt.py", line 142, in decode
    payload = jws.verify(token, key, algorithms, verify=verify_signature)
  File "C:\Users\sslinnn\Desktop\PartyFinder\.venv\Lib\site-packages\jose\jws.py", line 70, in verify
    header, payload, signing_input, signature = _load(token)
                                                ~~~~~^^^^^^^
  File "C:\Users\sslinnn\Desktop\PartyFinder\.venv\Lib\site-packages\jose\jws.py", line 176, in _load
    signing_input, crypto_segment = jwt.rsplit(b".", 1)
                                    ^^^^^^^^^^
AttributeError: 'NoneType' object has no attribute 'rsplit'
2025-02-22 22:32:17 - app - INFO - Логирование успешно настроено
2025-02-22 22:32:25 - middleware.error_handler - INFO - Входящий запрос: POST http://localhost:8000/api/auth/login
2025-02-22 22:32:25 - api.auth.router - INFO - Попытка входа пользователя: morison1991@mail.ru
2025-02-22 22:32:25 - middleware.error_handler - INFO - Исходящий ответ: 200
2025-02-22 22:32:25 - middleware.error_handler - INFO - Входящий запрос: GET http://localhost:8000/api/users/me
2025-02-22 22:32:25 - middleware.error_handler - ERROR - Необработанное исключение: 'NoneType' object has no attribute 'rsplit'
Traceback (most recent call last):
  File "C:\Users\sslinnn\Desktop\PartyFinder\.venv\Lib\site-packages\anyio\streams\memory.py", line 111, in receive
    return self.receive_nowait()
           ~~~~~~~~~~~~~~~~~~~^^
  File "C:\Users\sslinnn\Desktop\PartyFinder\.venv\Lib\site-packages\anyio\streams\memory.py", line 106, in receive_nowait
    raise WouldBlock
anyio.WouldBlock

During handling of the above exception, another exception occurred:

Traceback (most recent call last):
  File "C:\Users\sslinnn\Desktop\PartyFinder\.venv\Lib\site-packages\anyio\streams\memory.py", line 124, in receive
    return receiver.item
           ^^^^^^^^^^^^^
AttributeError: 'MemoryObjectItemReceiver' object has no attribute 'item'

During handling of the above exception, another exception occurred:

Traceback (most recent call last):
  File "C:\Users\sslinnn\Desktop\PartyFinder\.venv\Lib\site-packages\starlette\middleware\base.py", line 157, in call_next
    message = await recv_stream.receive()
              ^^^^^^^^^^^^^^^^^^^^^^^^^^^
  File "C:\Users\sslinnn\Desktop\PartyFinder\.venv\Lib\site-packages\anyio\streams\memory.py", line 126, in receive
    raise EndOfStream
anyio.EndOfStream

During handling of the above exception, another exception occurred:

Traceback (most recent call last):
  File "C:\Users\sslinnn\Desktop\PartyFinder\middleware\error_handler.py", line 12, in error_handler
    response = await call_next(request)
               ^^^^^^^^^^^^^^^^^^^^^^^^
  File "C:\Users\sslinnn\Desktop\PartyFinder\.venv\Lib\site-packages\starlette\middleware\base.py", line 163, in call_next
    raise app_exc
  File "C:\Users\sslinnn\Desktop\PartyFinder\.venv\Lib\site-packages\starlette\middleware\base.py", line 149, in coro
    await self.app(scope, receive_or_disconnect, send_no_error)
  File "C:\Users\sslinnn\Desktop\PartyFinder\.venv\Lib\site-packages\starlette\middleware\exceptions.py", line 62, in __call__
    await wrap_app_handling_exceptions(self.app, conn)(scope, receive, send)
  File "C:\Users\sslinnn\Desktop\PartyFinder\.venv\Lib\site-packages\starlette\_exception_handler.py", line 53, in wrapped_app
    raise exc
  File "C:\Users\sslinnn\Desktop\PartyFinder\.venv\Lib\site-packages\starlette\_exception_handler.py", line 42, in wrapped_app
    await app(scope, receive, sender)
  File "C:\Users\sslinnn\Desktop\PartyFinder\.venv\Lib\site-packages\starlette\routing.py", line 715, in __call__
    await self.middleware_stack(scope, receive, send)
  File "C:\Users\sslinnn\Desktop\PartyFinder\.venv\Lib\site-packages\starlette\routing.py", line 735, in app
    await route.handle(scope, receive, send)
  File "C:\Users\sslinnn\Desktop\PartyFinder\.venv\Lib\site-packages\starlette\routing.py", line 288, in handle
    await self.app(scope, receive, send)
  File "C:\Users\sslinnn\Desktop\PartyFinder\.venv\Lib\site-packages\starlette\routing.py", line 76, in app
    await wrap_app_handling_exceptions(app, request)(scope, receive, send)
  File "C:\Users\sslinnn\Desktop\PartyFinder\.venv\Lib\site-packages\starlette\_exception_handler.py", line 53, in wrapped_app
    raise exc
  File "C:\Users\sslinnn\Desktop\PartyFinder\.venv\Lib\site-packages\starlette\_exception_handler.py", line 42, in wrapped_app
    await app(scope, receive, sender)
  File "C:\Users\sslinnn\Desktop\PartyFinder\.venv\Lib\site-packages\starlette\routing.py", line 73, in app
    response = await f(request)
               ^^^^^^^^^^^^^^^^
  File "C:\Users\sslinnn\Desktop\PartyFinder\.venv\Lib\site-packages\fastapi\routing.py", line 291, in app
    solved_result = await solve_dependencies(
                    ^^^^^^^^^^^^^^^^^^^^^^^^^
    ...<6 lines>...
    )
    ^
  File "C:\Users\sslinnn\Desktop\PartyFinder\.venv\Lib\site-packages\fastapi\dependencies\utils.py", line 638, in solve_dependencies
    solved = await call(**solved_result.values)
             ^^^^^^^^^^^^^^^^^^^^^^^^^^^^^^^^^^
  File "C:\Users\sslinnn\Desktop\PartyFinder\api\users\users_utils.py", line 21, in get_current_user
    if not token:
              ^^^
  File "C:\Users\sslinnn\Desktop\PartyFinder\utils\JWTUtils.py", line 31, in decode_access_token
    
    auth_data = get_auth_data()
    try:
  File "C:\Users\sslinnn\Desktop\PartyFinder\.venv\Lib\site-packages\jose\jwt.py", line 142, in decode
    payload = jws.verify(token, key, algorithms, verify=verify_signature)
  File "C:\Users\sslinnn\Desktop\PartyFinder\.venv\Lib\site-packages\jose\jws.py", line 70, in verify
    header, payload, signing_input, signature = _load(token)
                                                ~~~~~^^^^^^^
  File "C:\Users\sslinnn\Desktop\PartyFinder\.venv\Lib\site-packages\jose\jws.py", line 176, in _load
    signing_input, crypto_segment = jwt.rsplit(b".", 1)
                                    ^^^^^^^^^^
AttributeError: 'NoneType' object has no attribute 'rsplit'
2025-02-22 22:32:50 - app - INFO - Логирование успешно настроено
2025-02-22 22:33:04 - app - INFO - Логирование успешно настроено
2025-02-22 22:33:08 - middleware.error_handler - INFO - Входящий запрос: POST http://localhost:8000/api/auth/login
2025-02-22 22:33:08 - api.auth.router - INFO - Попытка входа пользователя: morison1991@mail.ru
2025-02-22 22:33:09 - middleware.error_handler - INFO - Исходящий ответ: 200
2025-02-22 22:33:09 - middleware.error_handler - INFO - Входящий запрос: GET http://localhost:8000/api/users/me
2025-02-22 22:33:09 - middleware.error_handler - INFO - Исходящий ответ: 401
2025-02-22 22:33:28 - middleware.error_handler - INFO - Входящий запрос: POST http://localhost:8000/api/auth/login
2025-02-22 22:33:28 - api.auth.router - INFO - Попытка входа пользователя: morison1991@mail.ru
2025-02-22 22:33:29 - middleware.error_handler - INFO - Исходящий ответ: 200
2025-02-22 22:33:29 - middleware.error_handler - INFO - Входящий запрос: GET http://localhost:8000/api/users/me
2025-02-22 22:33:29 - middleware.error_handler - INFO - Исходящий ответ: 401
2025-02-22 22:35:32 - app - INFO - Логирование успешно настроено
2025-02-22 22:37:29 - middleware.error_handler - INFO - Входящий запрос: POST http://localhost:8000/api/auth/login
2025-02-22 22:37:29 - api.auth.router - INFO - Попытка входа пользователя: morison1991@mail.ru
2025-02-22 22:37:29 - middleware.error_handler - INFO - Исходящий ответ: 200
2025-02-22 22:37:30 - middleware.error_handler - INFO - Входящий запрос: GET http://localhost:8000/api/users/me
2025-02-22 22:37:30 - middleware.error_handler - INFO - Исходящий ответ: 401
2025-02-22 22:37:47 - middleware.error_handler - INFO - Входящий запрос: POST http://localhost:8000/api/auth/login
2025-02-22 22:37:47 - api.auth.router - INFO - Попытка входа пользователя: morison1991@mail.ru
2025-02-22 22:37:47 - middleware.error_handler - INFO - Исходящий ответ: 200
2025-02-22 22:37:47 - middleware.error_handler - INFO - Входящий запрос: GET http://localhost:8000/api/users/me
2025-02-22 22:37:47 - middleware.error_handler - INFO - Исходящий ответ: 401
2025-02-22 22:55:42 - app - INFO - Приложение запущено
2025-02-22 22:55:42 - app - INFO - Приложение запущено
2025-02-22 22:55:52 - middleware.error_handler - INFO - Входящий запрос: POST http://localhost:8000/api/auth/login
2025-02-22 22:55:52 - api.auth.router - INFO - Попытка входа пользователя: morison1991@mail.ru
2025-02-22 22:55:52 - middleware.error_handler - INFO - Исходящий ответ: 200
2025-02-22 22:55:52 - middleware.error_handler - INFO - Входящий запрос: GET http://localhost:8000/api/users/me
2025-02-22 22:55:52 - middleware.error_handler - INFO - Исходящий ответ: 401
2025-02-22 22:58:01 - middleware.error_handler - INFO - Входящий запрос: POST http://localhost:8000/api/auth/login
2025-02-22 22:58:01 - api.auth.router - INFO - Попытка входа пользователя: morison1991@mail.ru
2025-02-22 22:58:01 - middleware.error_handler - INFO - Исходящий ответ: 200
2025-02-22 22:58:01 - middleware.error_handler - INFO - Входящий запрос: GET http://localhost:8000/api/users/me
2025-02-22 22:58:01 - middleware.error_handler - INFO - Исходящий ответ: 401
2025-02-22 22:58:07 - app - INFO - Приложение остановлено
2025-02-22 22:58:09 - app - INFO - Приложение запущено
2025-02-22 22:58:09 - app - INFO - Приложение остановлено
2025-02-22 22:58:11 - app - INFO - Приложение запущено
2025-02-22 22:58:13 - middleware.error_handler - INFO - Входящий запрос: POST http://localhost:8000/api/auth/login
2025-02-22 22:58:13 - api.auth.router - INFO - Попытка входа пользователя: morison1991@mail.ru
2025-02-22 22:58:14 - middleware.error_handler - INFO - Исходящий ответ: 200
2025-02-22 22:58:14 - middleware.error_handler - INFO - Входящий запрос: GET http://localhost:8000/api/users/me
2025-02-22 22:58:14 - middleware.error_handler - INFO - Исходящий ответ: 401
2025-02-22 22:58:30 - middleware.error_handler - INFO - Входящий запрос: POST http://localhost:8000/api/auth/login
2025-02-22 22:58:30 - api.auth.router - INFO - Попытка входа пользователя: morison1991@mail.ru
2025-02-22 22:58:30 - middleware.error_handler - INFO - Исходящий ответ: 200
2025-02-22 22:58:30 - middleware.error_handler - INFO - Входящий запрос: GET http://localhost:8000/api/users/me
2025-02-22 22:58:30 - middleware.error_handler - INFO - Исходящий ответ: 401
2025-02-22 22:59:39 - middleware.error_handler - INFO - Входящий запрос: GET http://127.0.0.1:8000/docs
2025-02-22 22:59:39 - middleware.error_handler - INFO - Исходящий ответ: 200
2025-02-22 22:59:40 - middleware.error_handler - INFO - Входящий запрос: GET http://127.0.0.1:8000/openapi.json
2025-02-22 22:59:40 - middleware.error_handler - INFO - Исходящий ответ: 200
2025-02-22 22:59:47 - middleware.error_handler - INFO - Входящий запрос: GET http://127.0.0.1:8000/api/auth/test-logging
2025-02-22 22:59:47 - api.auth.router - INFO - Это info сообщение
2025-02-22 22:59:47 - api.auth.router - WARNING - Это warning сообщение
2025-02-22 22:59:47 - api.auth.router - ERROR - Это error сообщение: Тестовая ошибка
Traceback (most recent call last):
  File "C:\Users\sslinnn\Desktop\PartyFinder\api\auth\router.py", line 73, in test_logging
ValueError: Тестовая ошибка
2025-02-22 22:59:47 - middleware.error_handler - INFO - Исходящий ответ: 200
2025-02-22 22:59:49 - middleware.error_handler - INFO - Входящий запрос: GET http://127.0.0.1:8000/api/auth/test-logging
2025-02-22 22:59:49 - api.auth.router - INFO - Это info сообщение
2025-02-22 22:59:49 - api.auth.router - WARNING - Это warning сообщение
2025-02-22 22:59:49 - api.auth.router - ERROR - Это error сообщение: Тестовая ошибка
Traceback (most recent call last):
  File "C:\Users\sslinnn\Desktop\PartyFinder\api\auth\router.py", line 73, in test_logging
ValueError: Тестовая ошибка
2025-02-22 22:59:49 - middleware.error_handler - INFO - Исходящий ответ: 200
2025-02-22 22:59:56 - app - INFO - Приложение остановлено
2025-02-22 23:00:09 - app - INFO - Приложение запущено
2025-02-22 23:00:14 - app - INFO - Приложение запущено
2025-02-22 23:00:23 - app - INFO - Приложение запущено
2025-02-22 23:00:31 - middleware.error_handler - INFO - Входящий запрос: POST http://localhost:8000/api/auth/login
2025-02-22 23:00:31 - api.auth.router - INFO - Попытка входа пользователя: morison1991@mail.ru
2025-02-22 23:00:32 - middleware.error_handler - ERROR - Необработанное исключение: 1 validation errors:
  {'type': 'model_attributes_type', 'loc': ('response',), 'msg': 'Input should be a valid dictionary or object to extract fields from', 'input': None}
Traceback (most recent call last):
  File "C:\Users\sslinnn\Desktop\PartyFinder\.venv\Lib\site-packages\anyio\streams\memory.py", line 111, in receive
    return self.receive_nowait()
           ~~~~~~~~~~~~~~~~~~~^^
  File "C:\Users\sslinnn\Desktop\PartyFinder\.venv\Lib\site-packages\anyio\streams\memory.py", line 106, in receive_nowait
    raise WouldBlock
anyio.WouldBlock

During handling of the above exception, another exception occurred:

Traceback (most recent call last):
  File "C:\Users\sslinnn\Desktop\PartyFinder\.venv\Lib\site-packages\anyio\streams\memory.py", line 124, in receive
    return receiver.item
           ^^^^^^^^^^^^^
AttributeError: 'MemoryObjectItemReceiver' object has no attribute 'item'

During handling of the above exception, another exception occurred:

Traceback (most recent call last):
  File "C:\Users\sslinnn\Desktop\PartyFinder\.venv\Lib\site-packages\starlette\middleware\base.py", line 157, in call_next
    message = await recv_stream.receive()
              ^^^^^^^^^^^^^^^^^^^^^^^^^^^
  File "C:\Users\sslinnn\Desktop\PartyFinder\.venv\Lib\site-packages\anyio\streams\memory.py", line 126, in receive
    raise EndOfStream
anyio.EndOfStream

During handling of the above exception, another exception occurred:

Traceback (most recent call last):
  File "C:\Users\sslinnn\Desktop\PartyFinder\middleware\error_handler.py", line 12, in error_handler
    response = await call_next(request)
               ^^^^^^^^^^^^^^^^^^^^^^^^
  File "C:\Users\sslinnn\Desktop\PartyFinder\.venv\Lib\site-packages\starlette\middleware\base.py", line 163, in call_next
    raise app_exc
  File "C:\Users\sslinnn\Desktop\PartyFinder\.venv\Lib\site-packages\starlette\middleware\base.py", line 149, in coro
    await self.app(scope, receive_or_disconnect, send_no_error)
  File "C:\Users\sslinnn\Desktop\PartyFinder\.venv\Lib\site-packages\starlette\middleware\exceptions.py", line 62, in __call__
    await wrap_app_handling_exceptions(self.app, conn)(scope, receive, send)
  File "C:\Users\sslinnn\Desktop\PartyFinder\.venv\Lib\site-packages\starlette\_exception_handler.py", line 53, in wrapped_app
    raise exc
  File "C:\Users\sslinnn\Desktop\PartyFinder\.venv\Lib\site-packages\starlette\_exception_handler.py", line 42, in wrapped_app
    await app(scope, receive, sender)
  File "C:\Users\sslinnn\Desktop\PartyFinder\.venv\Lib\site-packages\starlette\routing.py", line 715, in __call__
    await self.middleware_stack(scope, receive, send)
  File "C:\Users\sslinnn\Desktop\PartyFinder\.venv\Lib\site-packages\starlette\routing.py", line 735, in app
    await route.handle(scope, receive, send)
  File "C:\Users\sslinnn\Desktop\PartyFinder\.venv\Lib\site-packages\starlette\routing.py", line 288, in handle
    await self.app(scope, receive, send)
  File "C:\Users\sslinnn\Desktop\PartyFinder\.venv\Lib\site-packages\starlette\routing.py", line 76, in app
    await wrap_app_handling_exceptions(app, request)(scope, receive, send)
  File "C:\Users\sslinnn\Desktop\PartyFinder\.venv\Lib\site-packages\starlette\_exception_handler.py", line 53, in wrapped_app
    raise exc
  File "C:\Users\sslinnn\Desktop\PartyFinder\.venv\Lib\site-packages\starlette\_exception_handler.py", line 42, in wrapped_app
    await app(scope, receive, sender)
  File "C:\Users\sslinnn\Desktop\PartyFinder\.venv\Lib\site-packages\starlette\routing.py", line 73, in app
    response = await f(request)
               ^^^^^^^^^^^^^^^^
  File "C:\Users\sslinnn\Desktop\PartyFinder\.venv\Lib\site-packages\fastapi\routing.py", line 327, in app
    content = await serialize_response(
              ^^^^^^^^^^^^^^^^^^^^^^^^^
    ...<9 lines>...
    )
    ^
  File "C:\Users\sslinnn\Desktop\PartyFinder\.venv\Lib\site-packages\fastapi\routing.py", line 176, in serialize_response
    raise ResponseValidationError(
        errors=_normalize_errors(errors), body=response_content
    )
fastapi.exceptions.ResponseValidationError: 1 validation errors:
  {'type': 'model_attributes_type', 'loc': ('response',), 'msg': 'Input should be a valid dictionary or object to extract fields from', 'input': None}

2025-02-22 23:01:12 - middleware.error_handler - INFO - Входящий запрос: POST http://localhost:8000/api/auth/login
2025-02-22 23:01:12 - api.auth.router - INFO - Попытка входа пользователя: morison1991@mail.ru
2025-02-22 23:01:13 - middleware.error_handler - ERROR - Необработанное исключение: 1 validation errors:
  {'type': 'model_attributes_type', 'loc': ('response',), 'msg': 'Input should be a valid dictionary or object to extract fields from', 'input': None}
Traceback (most recent call last):
  File "C:\Users\sslinnn\Desktop\PartyFinder\.venv\Lib\site-packages\anyio\streams\memory.py", line 111, in receive
    return self.receive_nowait()
           ~~~~~~~~~~~~~~~~~~~^^
  File "C:\Users\sslinnn\Desktop\PartyFinder\.venv\Lib\site-packages\anyio\streams\memory.py", line 106, in receive_nowait
    raise WouldBlock
anyio.WouldBlock

During handling of the above exception, another exception occurred:

Traceback (most recent call last):
  File "C:\Users\sslinnn\Desktop\PartyFinder\.venv\Lib\site-packages\anyio\streams\memory.py", line 124, in receive
    return receiver.item
           ^^^^^^^^^^^^^
AttributeError: 'MemoryObjectItemReceiver' object has no attribute 'item'

During handling of the above exception, another exception occurred:

Traceback (most recent call last):
  File "C:\Users\sslinnn\Desktop\PartyFinder\.venv\Lib\site-packages\starlette\middleware\base.py", line 157, in call_next
    message = await recv_stream.receive()
              ^^^^^^^^^^^^^^^^^^^^^^^^^^^
  File "C:\Users\sslinnn\Desktop\PartyFinder\.venv\Lib\site-packages\anyio\streams\memory.py", line 126, in receive
    raise EndOfStream
anyio.EndOfStream

During handling of the above exception, another exception occurred:

Traceback (most recent call last):
  File "C:\Users\sslinnn\Desktop\PartyFinder\middleware\error_handler.py", line 12, in error_handler
    response = await call_next(request)
               ^^^^^^^^^^^^^^^^^^^^^^^^
  File "C:\Users\sslinnn\Desktop\PartyFinder\.venv\Lib\site-packages\starlette\middleware\base.py", line 163, in call_next
    raise app_exc
  File "C:\Users\sslinnn\Desktop\PartyFinder\.venv\Lib\site-packages\starlette\middleware\base.py", line 149, in coro
    await self.app(scope, receive_or_disconnect, send_no_error)
  File "C:\Users\sslinnn\Desktop\PartyFinder\.venv\Lib\site-packages\starlette\middleware\exceptions.py", line 62, in __call__
    await wrap_app_handling_exceptions(self.app, conn)(scope, receive, send)
  File "C:\Users\sslinnn\Desktop\PartyFinder\.venv\Lib\site-packages\starlette\_exception_handler.py", line 53, in wrapped_app
    raise exc
  File "C:\Users\sslinnn\Desktop\PartyFinder\.venv\Lib\site-packages\starlette\_exception_handler.py", line 42, in wrapped_app
    await app(scope, receive, sender)
  File "C:\Users\sslinnn\Desktop\PartyFinder\.venv\Lib\site-packages\starlette\routing.py", line 715, in __call__
    await self.middleware_stack(scope, receive, send)
  File "C:\Users\sslinnn\Desktop\PartyFinder\.venv\Lib\site-packages\starlette\routing.py", line 735, in app
    await route.handle(scope, receive, send)
  File "C:\Users\sslinnn\Desktop\PartyFinder\.venv\Lib\site-packages\starlette\routing.py", line 288, in handle
    await self.app(scope, receive, send)
  File "C:\Users\sslinnn\Desktop\PartyFinder\.venv\Lib\site-packages\starlette\routing.py", line 76, in app
    await wrap_app_handling_exceptions(app, request)(scope, receive, send)
  File "C:\Users\sslinnn\Desktop\PartyFinder\.venv\Lib\site-packages\starlette\_exception_handler.py", line 53, in wrapped_app
    raise exc
  File "C:\Users\sslinnn\Desktop\PartyFinder\.venv\Lib\site-packages\starlette\_exception_handler.py", line 42, in wrapped_app
    await app(scope, receive, sender)
  File "C:\Users\sslinnn\Desktop\PartyFinder\.venv\Lib\site-packages\starlette\routing.py", line 73, in app
    response = await f(request)
               ^^^^^^^^^^^^^^^^
  File "C:\Users\sslinnn\Desktop\PartyFinder\.venv\Lib\site-packages\fastapi\routing.py", line 327, in app
    content = await serialize_response(
              ^^^^^^^^^^^^^^^^^^^^^^^^^
    ...<9 lines>...
    )
    ^
  File "C:\Users\sslinnn\Desktop\PartyFinder\.venv\Lib\site-packages\fastapi\routing.py", line 176, in serialize_response
    raise ResponseValidationError(
        errors=_normalize_errors(errors), body=response_content
    )
fastapi.exceptions.ResponseValidationError: 1 validation errors:
  {'type': 'model_attributes_type', 'loc': ('response',), 'msg': 'Input should be a valid dictionary or object to extract fields from', 'input': None}

2025-02-22 23:03:17 - middleware.error_handler - INFO - Входящий запрос: POST http://localhost:8000/api/auth/login
2025-02-22 23:03:17 - api.auth.router - INFO - Попытка входа пользователя: morison1991@mail.ru
2025-02-22 23:03:18 - middleware.error_handler - ERROR - Необработанное исключение: 1 validation errors:
  {'type': 'model_attributes_type', 'loc': ('response',), 'msg': 'Input should be a valid dictionary or object to extract fields from', 'input': None}
Traceback (most recent call last):
  File "C:\Users\sslinnn\Desktop\PartyFinder\.venv\Lib\site-packages\anyio\streams\memory.py", line 111, in receive
    return self.receive_nowait()
           ~~~~~~~~~~~~~~~~~~~^^
  File "C:\Users\sslinnn\Desktop\PartyFinder\.venv\Lib\site-packages\anyio\streams\memory.py", line 106, in receive_nowait
    raise WouldBlock
anyio.WouldBlock

During handling of the above exception, another exception occurred:

Traceback (most recent call last):
  File "C:\Users\sslinnn\Desktop\PartyFinder\.venv\Lib\site-packages\anyio\streams\memory.py", line 124, in receive
    return receiver.item
           ^^^^^^^^^^^^^
AttributeError: 'MemoryObjectItemReceiver' object has no attribute 'item'

During handling of the above exception, another exception occurred:

Traceback (most recent call last):
  File "C:\Users\sslinnn\Desktop\PartyFinder\.venv\Lib\site-packages\starlette\middleware\base.py", line 157, in call_next
    message = await recv_stream.receive()
              ^^^^^^^^^^^^^^^^^^^^^^^^^^^
  File "C:\Users\sslinnn\Desktop\PartyFinder\.venv\Lib\site-packages\anyio\streams\memory.py", line 126, in receive
    raise EndOfStream
anyio.EndOfStream

During handling of the above exception, another exception occurred:

Traceback (most recent call last):
  File "C:\Users\sslinnn\Desktop\PartyFinder\middleware\error_handler.py", line 12, in error_handler
    response = await call_next(request)
               ^^^^^^^^^^^^^^^^^^^^^^^^
  File "C:\Users\sslinnn\Desktop\PartyFinder\.venv\Lib\site-packages\starlette\middleware\base.py", line 163, in call_next
    raise app_exc
  File "C:\Users\sslinnn\Desktop\PartyFinder\.venv\Lib\site-packages\starlette\middleware\base.py", line 149, in coro
    await self.app(scope, receive_or_disconnect, send_no_error)
  File "C:\Users\sslinnn\Desktop\PartyFinder\.venv\Lib\site-packages\starlette\middleware\exceptions.py", line 62, in __call__
    await wrap_app_handling_exceptions(self.app, conn)(scope, receive, send)
  File "C:\Users\sslinnn\Desktop\PartyFinder\.venv\Lib\site-packages\starlette\_exception_handler.py", line 53, in wrapped_app
    raise exc
  File "C:\Users\sslinnn\Desktop\PartyFinder\.venv\Lib\site-packages\starlette\_exception_handler.py", line 42, in wrapped_app
    await app(scope, receive, sender)
  File "C:\Users\sslinnn\Desktop\PartyFinder\.venv\Lib\site-packages\starlette\routing.py", line 715, in __call__
    await self.middleware_stack(scope, receive, send)
  File "C:\Users\sslinnn\Desktop\PartyFinder\.venv\Lib\site-packages\starlette\routing.py", line 735, in app
    await route.handle(scope, receive, send)
  File "C:\Users\sslinnn\Desktop\PartyFinder\.venv\Lib\site-packages\starlette\routing.py", line 288, in handle
    await self.app(scope, receive, send)
  File "C:\Users\sslinnn\Desktop\PartyFinder\.venv\Lib\site-packages\starlette\routing.py", line 76, in app
    await wrap_app_handling_exceptions(app, request)(scope, receive, send)
  File "C:\Users\sslinnn\Desktop\PartyFinder\.venv\Lib\site-packages\starlette\_exception_handler.py", line 53, in wrapped_app
    raise exc
  File "C:\Users\sslinnn\Desktop\PartyFinder\.venv\Lib\site-packages\starlette\_exception_handler.py", line 42, in wrapped_app
    await app(scope, receive, sender)
  File "C:\Users\sslinnn\Desktop\PartyFinder\.venv\Lib\site-packages\starlette\routing.py", line 73, in app
    response = await f(request)
               ^^^^^^^^^^^^^^^^
  File "C:\Users\sslinnn\Desktop\PartyFinder\.venv\Lib\site-packages\fastapi\routing.py", line 327, in app
    content = await serialize_response(
              ^^^^^^^^^^^^^^^^^^^^^^^^^
    ...<9 lines>...
    )
    ^
  File "C:\Users\sslinnn\Desktop\PartyFinder\.venv\Lib\site-packages\fastapi\routing.py", line 176, in serialize_response
    raise ResponseValidationError(
        errors=_normalize_errors(errors), body=response_content
    )
fastapi.exceptions.ResponseValidationError: 1 validation errors:
  {'type': 'model_attributes_type', 'loc': ('response',), 'msg': 'Input should be a valid dictionary or object to extract fields from', 'input': None}

2025-02-22 23:03:22 - app - INFO - Приложение запущено
2025-02-22 23:03:24 - middleware.error_handler - INFO - Входящий запрос: POST http://localhost:8000/api/auth/login
2025-02-22 23:03:24 - api.auth.router - INFO - Попытка входа пользователя: morison1991@mail.ru
2025-02-22 23:03:25 - middleware.error_handler - INFO - Исходящий ответ: 200
2025-02-22 23:03:25 - middleware.error_handler - INFO - Входящий запрос: GET http://localhost:8000/api/users/me
2025-02-22 23:03:25 - app - INFO - Запрос данных пользователя: 37
2025-02-22 23:03:25 - middleware.error_handler - INFO - Исходящий ответ: 200
2025-02-22 23:03:47 - middleware.error_handler - INFO - Входящий запрос: PATCH http://localhost:8000/api/users/update
2025-02-22 23:03:47 - app - INFO - Запрос на обновление пользователя: 37
2025-02-22 23:03:47 - services.user_service - INFO - Попытка обновления пользователя с ID: 37
2025-02-22 23:03:47 - services.user_service - INFO - Пользователь успешно обновлен: 37
2025-02-22 23:03:47 - middleware.error_handler - INFO - Исходящий ответ: 200
2025-02-22 23:03:47 - middleware.error_handler - INFO - Входящий запрос: GET http://localhost:8000/api/users/me
2025-02-22 23:03:47 - app - INFO - Запрос данных пользователя: 37
2025-02-22 23:03:47 - middleware.error_handler - INFO - Исходящий ответ: 200
2025-02-22 23:03:53 - middleware.error_handler - INFO - Входящий запрос: PATCH http://localhost:8000/api/users/update
2025-02-22 23:03:53 - app - INFO - Запрос на обновление пользователя: 37
2025-02-22 23:03:53 - services.user_service - INFO - Попытка обновления пользователя с ID: 37
2025-02-22 23:03:53 - services.user_service - INFO - Пользователь успешно обновлен: 37
2025-02-22 23:03:53 - middleware.error_handler - INFO - Исходящий ответ: 200
2025-02-22 23:03:53 - middleware.error_handler - INFO - Входящий запрос: GET http://localhost:8000/api/users/me
2025-02-22 23:03:53 - app - INFO - Запрос данных пользователя: 37
2025-02-22 23:03:53 - middleware.error_handler - INFO - Исходящий ответ: 200
2025-02-22 23:04:01 - middleware.error_handler - INFO - Входящий запрос: PATCH http://localhost:8000/api/users/update
2025-02-22 23:04:01 - app - INFO - Запрос на обновление пользователя: 37
2025-02-22 23:04:01 - services.user_service - INFO - Попытка обновления пользователя с ID: 37
2025-02-22 23:04:01 - services.user_service - INFO - Пользователь успешно обновлен: 37
2025-02-22 23:04:01 - middleware.error_handler - INFO - Исходящий ответ: 200
2025-02-22 23:04:01 - middleware.error_handler - INFO - Входящий запрос: GET http://localhost:8000/api/users/me
2025-02-22 23:04:01 - app - INFO - Запрос данных пользователя: 37
2025-02-22 23:04:01 - middleware.error_handler - INFO - Исходящий ответ: 200
2025-02-22 23:07:22 - middleware.error_handler - INFO - Входящий запрос: GET http://localhost:8000/api/auth/logout
2025-02-22 23:07:22 - middleware.error_handler - INFO - Исходящий ответ: 405
2025-02-22 23:08:20 - app - INFO - Приложение остановлено
2025-02-22 23:09:10 - app - INFO - Приложение запущено
2025-02-22 23:09:13 - app - INFO - Приложение запущено
2025-02-22 23:09:16 - middleware.error_handler - INFO - Входящий запрос: GET http://localhost:8000/api/auth/logout
2025-02-22 23:09:16 - middleware.error_handler - INFO - Исходящий ответ: 200
2025-02-22 23:09:21 - middleware.error_handler - INFO - Входящий запрос: POST http://localhost:8000/api/auth/login
2025-02-22 23:09:21 - api.auth.router - INFO - Попытка входа пользователя: morison1991@mail.ru
2025-02-22 23:09:22 - middleware.error_handler - INFO - Исходящий ответ: 200
2025-02-22 23:09:22 - middleware.error_handler - INFO - Входящий запрос: GET http://localhost:8000/api/users/me
2025-02-22 23:09:22 - app - INFO - Запрос данных пользователя: 37
2025-02-22 23:09:22 - middleware.error_handler - INFO - Исходящий ответ: 200
2025-02-22 23:09:29 - middleware.error_handler - INFO - Входящий запрос: GET http://localhost:8000/api/auth/logout
2025-02-22 23:09:29 - middleware.error_handler - INFO - Исходящий ответ: 200
2025-02-22 23:09:42 - middleware.error_handler - INFO - Входящий запрос: POST http://localhost:8000/api/auth/register
2025-02-22 23:09:42 - api.auth.router - INFO - Запрос на регистрацию пользователя: asdwa@mail.ru
2025-02-22 23:09:42 - api.auth.auth_utils - INFO - Попытка создания пользователя с email: asdwa@mail.ru
2025-02-22 23:09:42 - api.auth.auth_utils - INFO - Пользователь успешно создан: 53
2025-02-22 23:09:42 - middleware.error_handler - ERROR - Необработанное исключение: 1 validation errors:
  {'type': 'bool_type', 'loc': ('response', 'email_confirmed'), 'msg': 'Input should be a valid boolean', 'input': None}
Traceback (most recent call last):
  File "C:\Users\sslinnn\Desktop\PartyFinder\.venv\Lib\site-packages\anyio\streams\memory.py", line 111, in receive
    return self.receive_nowait()
           ~~~~~~~~~~~~~~~~~~~^^
  File "C:\Users\sslinnn\Desktop\PartyFinder\.venv\Lib\site-packages\anyio\streams\memory.py", line 106, in receive_nowait
    raise WouldBlock
anyio.WouldBlock

During handling of the above exception, another exception occurred:

Traceback (most recent call last):
  File "C:\Users\sslinnn\Desktop\PartyFinder\.venv\Lib\site-packages\anyio\streams\memory.py", line 124, in receive
    return receiver.item
           ^^^^^^^^^^^^^
AttributeError: 'MemoryObjectItemReceiver' object has no attribute 'item'

During handling of the above exception, another exception occurred:

Traceback (most recent call last):
  File "C:\Users\sslinnn\Desktop\PartyFinder\.venv\Lib\site-packages\starlette\middleware\base.py", line 157, in call_next
    message = await recv_stream.receive()
              ^^^^^^^^^^^^^^^^^^^^^^^^^^^
  File "C:\Users\sslinnn\Desktop\PartyFinder\.venv\Lib\site-packages\anyio\streams\memory.py", line 126, in receive
    raise EndOfStream
anyio.EndOfStream

During handling of the above exception, another exception occurred:

Traceback (most recent call last):
  File "C:\Users\sslinnn\Desktop\PartyFinder\middleware\error_handler.py", line 12, in error_handler
    response = await call_next(request)
               ^^^^^^^^^^^^^^^^^^^^^^^^
  File "C:\Users\sslinnn\Desktop\PartyFinder\.venv\Lib\site-packages\starlette\middleware\base.py", line 163, in call_next
    raise app_exc
  File "C:\Users\sslinnn\Desktop\PartyFinder\.venv\Lib\site-packages\starlette\middleware\base.py", line 149, in coro
    await self.app(scope, receive_or_disconnect, send_no_error)
  File "C:\Users\sslinnn\Desktop\PartyFinder\.venv\Lib\site-packages\starlette\middleware\exceptions.py", line 62, in __call__
    await wrap_app_handling_exceptions(self.app, conn)(scope, receive, send)
  File "C:\Users\sslinnn\Desktop\PartyFinder\.venv\Lib\site-packages\starlette\_exception_handler.py", line 53, in wrapped_app
    raise exc
  File "C:\Users\sslinnn\Desktop\PartyFinder\.venv\Lib\site-packages\starlette\_exception_handler.py", line 42, in wrapped_app
    await app(scope, receive, sender)
  File "C:\Users\sslinnn\Desktop\PartyFinder\.venv\Lib\site-packages\starlette\routing.py", line 715, in __call__
    await self.middleware_stack(scope, receive, send)
  File "C:\Users\sslinnn\Desktop\PartyFinder\.venv\Lib\site-packages\starlette\routing.py", line 735, in app
    await route.handle(scope, receive, send)
  File "C:\Users\sslinnn\Desktop\PartyFinder\.venv\Lib\site-packages\starlette\routing.py", line 288, in handle
    await self.app(scope, receive, send)
  File "C:\Users\sslinnn\Desktop\PartyFinder\.venv\Lib\site-packages\starlette\routing.py", line 76, in app
    await wrap_app_handling_exceptions(app, request)(scope, receive, send)
  File "C:\Users\sslinnn\Desktop\PartyFinder\.venv\Lib\site-packages\starlette\_exception_handler.py", line 53, in wrapped_app
    raise exc
  File "C:\Users\sslinnn\Desktop\PartyFinder\.venv\Lib\site-packages\starlette\_exception_handler.py", line 42, in wrapped_app
    await app(scope, receive, sender)
  File "C:\Users\sslinnn\Desktop\PartyFinder\.venv\Lib\site-packages\starlette\routing.py", line 73, in app
    response = await f(request)
               ^^^^^^^^^^^^^^^^
  File "C:\Users\sslinnn\Desktop\PartyFinder\.venv\Lib\site-packages\fastapi\routing.py", line 327, in app
    content = await serialize_response(
              ^^^^^^^^^^^^^^^^^^^^^^^^^
    ...<9 lines>...
    )
    ^
  File "C:\Users\sslinnn\Desktop\PartyFinder\.venv\Lib\site-packages\fastapi\routing.py", line 176, in serialize_response
    raise ResponseValidationError(
        errors=_normalize_errors(errors), body=response_content
    )
fastapi.exceptions.ResponseValidationError: 1 validation errors:
  {'type': 'bool_type', 'loc': ('response', 'email_confirmed'), 'msg': 'Input should be a valid boolean', 'input': None}

2025-02-22 23:11:12 - app - INFO - Приложение запущено
2025-02-22 23:11:13 - middleware.error_handler - INFO - Входящий запрос: POST http://localhost:8000/api/auth/register
2025-02-22 23:11:13 - api.auth.router - INFO - Запрос на регистрацию пользователя: asdwa@mail.ru
2025-02-22 23:11:13 - api.auth.auth_utils - INFO - Попытка создания пользователя с email: asdwa@mail.ru
2025-02-22 23:11:13 - api.auth.auth_utils - WARNING - Попытка регистрации с существующим email: asdwa@mail.ru
2025-02-22 23:11:13 - api.auth.auth_utils - ERROR - Ошибка при создании пользователя: 400: User with this email already exists
2025-02-22 23:11:13 - middleware.error_handler - INFO - Исходящий ответ: 400
2025-02-22 23:11:22 - middleware.error_handler - INFO - Входящий запрос: POST http://localhost:8000/api/auth/register
2025-02-22 23:11:22 - api.auth.router - INFO - Запрос на регистрацию пользователя: asdwadasdwa@mail.ru
2025-02-22 23:11:22 - api.auth.auth_utils - INFO - Попытка создания пользователя с email: asdwadasdwa@mail.ru
2025-02-22 23:11:22 - api.auth.auth_utils - INFO - Пользователь успешно создан: 54
2025-02-22 23:11:22 - middleware.error_handler - ERROR - Необработанное исключение: 1 validation errors:
  {'type': 'bool_type', 'loc': ('response', 'email_confirmed'), 'msg': 'Input should be a valid boolean', 'input': None}
Traceback (most recent call last):
  File "C:\Users\sslinnn\Desktop\PartyFinder\.venv\Lib\site-packages\anyio\streams\memory.py", line 111, in receive
    return self.receive_nowait()
           ~~~~~~~~~~~~~~~~~~~^^
  File "C:\Users\sslinnn\Desktop\PartyFinder\.venv\Lib\site-packages\anyio\streams\memory.py", line 106, in receive_nowait
    raise WouldBlock
anyio.WouldBlock

During handling of the above exception, another exception occurred:

Traceback (most recent call last):
  File "C:\Users\sslinnn\Desktop\PartyFinder\.venv\Lib\site-packages\anyio\streams\memory.py", line 124, in receive
    return receiver.item
           ^^^^^^^^^^^^^
AttributeError: 'MemoryObjectItemReceiver' object has no attribute 'item'

During handling of the above exception, another exception occurred:

Traceback (most recent call last):
  File "C:\Users\sslinnn\Desktop\PartyFinder\.venv\Lib\site-packages\starlette\middleware\base.py", line 157, in call_next
    message = await recv_stream.receive()
              ^^^^^^^^^^^^^^^^^^^^^^^^^^^
  File "C:\Users\sslinnn\Desktop\PartyFinder\.venv\Lib\site-packages\anyio\streams\memory.py", line 126, in receive
    raise EndOfStream
anyio.EndOfStream

During handling of the above exception, another exception occurred:

Traceback (most recent call last):
  File "C:\Users\sslinnn\Desktop\PartyFinder\middleware\error_handler.py", line 12, in error_handler
    response = await call_next(request)
               ^^^^^^^^^^^^^^^^^^^^^^^^
  File "C:\Users\sslinnn\Desktop\PartyFinder\.venv\Lib\site-packages\starlette\middleware\base.py", line 163, in call_next
    raise app_exc
  File "C:\Users\sslinnn\Desktop\PartyFinder\.venv\Lib\site-packages\starlette\middleware\base.py", line 149, in coro
    await self.app(scope, receive_or_disconnect, send_no_error)
  File "C:\Users\sslinnn\Desktop\PartyFinder\.venv\Lib\site-packages\starlette\middleware\exceptions.py", line 62, in __call__
    await wrap_app_handling_exceptions(self.app, conn)(scope, receive, send)
  File "C:\Users\sslinnn\Desktop\PartyFinder\.venv\Lib\site-packages\starlette\_exception_handler.py", line 53, in wrapped_app
    raise exc
  File "C:\Users\sslinnn\Desktop\PartyFinder\.venv\Lib\site-packages\starlette\_exception_handler.py", line 42, in wrapped_app
    await app(scope, receive, sender)
  File "C:\Users\sslinnn\Desktop\PartyFinder\.venv\Lib\site-packages\starlette\routing.py", line 715, in __call__
    await self.middleware_stack(scope, receive, send)
  File "C:\Users\sslinnn\Desktop\PartyFinder\.venv\Lib\site-packages\starlette\routing.py", line 735, in app
    await route.handle(scope, receive, send)
  File "C:\Users\sslinnn\Desktop\PartyFinder\.venv\Lib\site-packages\starlette\routing.py", line 288, in handle
    await self.app(scope, receive, send)
  File "C:\Users\sslinnn\Desktop\PartyFinder\.venv\Lib\site-packages\starlette\routing.py", line 76, in app
    await wrap_app_handling_exceptions(app, request)(scope, receive, send)
  File "C:\Users\sslinnn\Desktop\PartyFinder\.venv\Lib\site-packages\starlette\_exception_handler.py", line 53, in wrapped_app
    raise exc
  File "C:\Users\sslinnn\Desktop\PartyFinder\.venv\Lib\site-packages\starlette\_exception_handler.py", line 42, in wrapped_app
    await app(scope, receive, sender)
  File "C:\Users\sslinnn\Desktop\PartyFinder\.venv\Lib\site-packages\starlette\routing.py", line 73, in app
    response = await f(request)
               ^^^^^^^^^^^^^^^^
  File "C:\Users\sslinnn\Desktop\PartyFinder\.venv\Lib\site-packages\fastapi\routing.py", line 327, in app
    content = await serialize_response(
              ^^^^^^^^^^^^^^^^^^^^^^^^^
    ...<9 lines>...
    )
    ^
  File "C:\Users\sslinnn\Desktop\PartyFinder\.venv\Lib\site-packages\fastapi\routing.py", line 176, in serialize_response
    raise ResponseValidationError(
        errors=_normalize_errors(errors), body=response_content
    )
fastapi.exceptions.ResponseValidationError: 1 validation errors:
  {'type': 'bool_type', 'loc': ('response', 'email_confirmed'), 'msg': 'Input should be a valid boolean', 'input': None}

2025-02-22 23:14:04 - app - INFO - Приложение запущено
2025-02-22 23:14:08 - middleware.error_handler - INFO - Входящий запрос: POST http://localhost:8000/api/auth/register
2025-02-22 23:14:08 - api.auth.router - INFO - Запрос на регистрацию пользователя: asdwadasdwa@mail.ru
2025-02-22 23:14:08 - api.auth.auth_utils - INFO - Попытка создания пользователя с email: asdwadasdwa@mail.ru
2025-02-22 23:14:08 - api.auth.auth_utils - WARNING - Попытка регистрации с существующим email: asdwadasdwa@mail.ru
2025-02-22 23:14:08 - api.auth.auth_utils - ERROR - Ошибка при создании пользователя: 400: User with this email already exists
2025-02-22 23:14:08 - middleware.error_handler - INFO - Исходящий ответ: 400
2025-02-22 23:14:50 - middleware.error_handler - INFO - Входящий запрос: POST http://localhost:8000/api/auth/register
2025-02-22 23:14:50 - api.auth.router - INFO - Запрос на регистрацию пользователя: asdwadaasdsdwa@mail.ru
2025-02-22 23:14:50 - api.auth.auth_utils - INFO - Попытка создания пользователя с email: asdwadaasdsdwa@mail.ru
2025-02-22 23:14:50 - api.auth.auth_utils - INFO - Пользователь успешно создан: 55
2025-02-22 23:14:50 - middleware.error_handler - ERROR - Необработанное исключение: 1 validation errors:
  {'type': 'bool_type', 'loc': ('response', 'email_confirmed'), 'msg': 'Input should be a valid boolean', 'input': None}
Traceback (most recent call last):
  File "C:\Users\sslinnn\Desktop\PartyFinder\.venv\Lib\site-packages\anyio\streams\memory.py", line 111, in receive
    return self.receive_nowait()
           ~~~~~~~~~~~~~~~~~~~^^
  File "C:\Users\sslinnn\Desktop\PartyFinder\.venv\Lib\site-packages\anyio\streams\memory.py", line 106, in receive_nowait
    raise WouldBlock
anyio.WouldBlock

During handling of the above exception, another exception occurred:

Traceback (most recent call last):
  File "C:\Users\sslinnn\Desktop\PartyFinder\.venv\Lib\site-packages\anyio\streams\memory.py", line 124, in receive
    return receiver.item
           ^^^^^^^^^^^^^
AttributeError: 'MemoryObjectItemReceiver' object has no attribute 'item'

During handling of the above exception, another exception occurred:

Traceback (most recent call last):
  File "C:\Users\sslinnn\Desktop\PartyFinder\.venv\Lib\site-packages\starlette\middleware\base.py", line 157, in call_next
    message = await recv_stream.receive()
              ^^^^^^^^^^^^^^^^^^^^^^^^^^^
  File "C:\Users\sslinnn\Desktop\PartyFinder\.venv\Lib\site-packages\anyio\streams\memory.py", line 126, in receive
    raise EndOfStream
anyio.EndOfStream

During handling of the above exception, another exception occurred:

Traceback (most recent call last):
  File "C:\Users\sslinnn\Desktop\PartyFinder\middleware\error_handler.py", line 12, in error_handler
    response = await call_next(request)
               ^^^^^^^^^^^^^^^^^^^^^^^^
  File "C:\Users\sslinnn\Desktop\PartyFinder\.venv\Lib\site-packages\starlette\middleware\base.py", line 163, in call_next
    raise app_exc
  File "C:\Users\sslinnn\Desktop\PartyFinder\.venv\Lib\site-packages\starlette\middleware\base.py", line 149, in coro
    await self.app(scope, receive_or_disconnect, send_no_error)
  File "C:\Users\sslinnn\Desktop\PartyFinder\.venv\Lib\site-packages\starlette\middleware\exceptions.py", line 62, in __call__
    await wrap_app_handling_exceptions(self.app, conn)(scope, receive, send)
  File "C:\Users\sslinnn\Desktop\PartyFinder\.venv\Lib\site-packages\starlette\_exception_handler.py", line 53, in wrapped_app
    raise exc
  File "C:\Users\sslinnn\Desktop\PartyFinder\.venv\Lib\site-packages\starlette\_exception_handler.py", line 42, in wrapped_app
    await app(scope, receive, sender)
  File "C:\Users\sslinnn\Desktop\PartyFinder\.venv\Lib\site-packages\starlette\routing.py", line 715, in __call__
    await self.middleware_stack(scope, receive, send)
  File "C:\Users\sslinnn\Desktop\PartyFinder\.venv\Lib\site-packages\starlette\routing.py", line 735, in app
    await route.handle(scope, receive, send)
  File "C:\Users\sslinnn\Desktop\PartyFinder\.venv\Lib\site-packages\starlette\routing.py", line 288, in handle
    await self.app(scope, receive, send)
  File "C:\Users\sslinnn\Desktop\PartyFinder\.venv\Lib\site-packages\starlette\routing.py", line 76, in app
    await wrap_app_handling_exceptions(app, request)(scope, receive, send)
  File "C:\Users\sslinnn\Desktop\PartyFinder\.venv\Lib\site-packages\starlette\_exception_handler.py", line 53, in wrapped_app
    raise exc
  File "C:\Users\sslinnn\Desktop\PartyFinder\.venv\Lib\site-packages\starlette\_exception_handler.py", line 42, in wrapped_app
    await app(scope, receive, sender)
  File "C:\Users\sslinnn\Desktop\PartyFinder\.venv\Lib\site-packages\starlette\routing.py", line 73, in app
    response = await f(request)
               ^^^^^^^^^^^^^^^^
  File "C:\Users\sslinnn\Desktop\PartyFinder\.venv\Lib\site-packages\fastapi\routing.py", line 327, in app
    content = await serialize_response(
              ^^^^^^^^^^^^^^^^^^^^^^^^^
    ...<9 lines>...
    )
    ^
  File "C:\Users\sslinnn\Desktop\PartyFinder\.venv\Lib\site-packages\fastapi\routing.py", line 176, in serialize_response
    raise ResponseValidationError(
        errors=_normalize_errors(errors), body=response_content
    )
fastapi.exceptions.ResponseValidationError: 1 validation errors:
  {'type': 'bool_type', 'loc': ('response', 'email_confirmed'), 'msg': 'Input should be a valid boolean', 'input': None}

2025-02-22 23:15:30 - middleware.error_handler - INFO - Входящий запрос: POST http://localhost:8000/api/auth/register
2025-02-22 23:15:30 - api.auth.router - INFO - Запрос на регистрацию пользователя: asdwaasddaasdsdwa@mail.ru
2025-02-22 23:15:30 - api.auth.auth_utils - INFO - Попытка создания пользователя с email: asdwaasddaasdsdwa@mail.ru
2025-02-22 23:15:31 - api.auth.auth_utils - INFO - Пользователь успешно создан: 56
2025-02-22 23:15:31 - middleware.error_handler - ERROR - Необработанное исключение: 1 validation errors:
  {'type': 'bool_type', 'loc': ('response', 'email_confirmed'), 'msg': 'Input should be a valid boolean', 'input': None}
Traceback (most recent call last):
  File "C:\Users\sslinnn\Desktop\PartyFinder\.venv\Lib\site-packages\anyio\streams\memory.py", line 111, in receive
    return self.receive_nowait()
           ~~~~~~~~~~~~~~~~~~~^^
  File "C:\Users\sslinnn\Desktop\PartyFinder\.venv\Lib\site-packages\anyio\streams\memory.py", line 106, in receive_nowait
    raise WouldBlock
anyio.WouldBlock

During handling of the above exception, another exception occurred:

Traceback (most recent call last):
  File "C:\Users\sslinnn\Desktop\PartyFinder\.venv\Lib\site-packages\anyio\streams\memory.py", line 124, in receive
    return receiver.item
           ^^^^^^^^^^^^^
AttributeError: 'MemoryObjectItemReceiver' object has no attribute 'item'

During handling of the above exception, another exception occurred:

Traceback (most recent call last):
  File "C:\Users\sslinnn\Desktop\PartyFinder\.venv\Lib\site-packages\starlette\middleware\base.py", line 157, in call_next
    message = await recv_stream.receive()
              ^^^^^^^^^^^^^^^^^^^^^^^^^^^
  File "C:\Users\sslinnn\Desktop\PartyFinder\.venv\Lib\site-packages\anyio\streams\memory.py", line 126, in receive
    raise EndOfStream
anyio.EndOfStream

During handling of the above exception, another exception occurred:

Traceback (most recent call last):
  File "C:\Users\sslinnn\Desktop\PartyFinder\middleware\error_handler.py", line 12, in error_handler
    response = await call_next(request)
               ^^^^^^^^^^^^^^^^^^^^^^^^
  File "C:\Users\sslinnn\Desktop\PartyFinder\.venv\Lib\site-packages\starlette\middleware\base.py", line 163, in call_next
    raise app_exc
  File "C:\Users\sslinnn\Desktop\PartyFinder\.venv\Lib\site-packages\starlette\middleware\base.py", line 149, in coro
    await self.app(scope, receive_or_disconnect, send_no_error)
  File "C:\Users\sslinnn\Desktop\PartyFinder\.venv\Lib\site-packages\starlette\middleware\exceptions.py", line 62, in __call__
    await wrap_app_handling_exceptions(self.app, conn)(scope, receive, send)
  File "C:\Users\sslinnn\Desktop\PartyFinder\.venv\Lib\site-packages\starlette\_exception_handler.py", line 53, in wrapped_app
    raise exc
  File "C:\Users\sslinnn\Desktop\PartyFinder\.venv\Lib\site-packages\starlette\_exception_handler.py", line 42, in wrapped_app
    await app(scope, receive, sender)
  File "C:\Users\sslinnn\Desktop\PartyFinder\.venv\Lib\site-packages\starlette\routing.py", line 715, in __call__
    await self.middleware_stack(scope, receive, send)
  File "C:\Users\sslinnn\Desktop\PartyFinder\.venv\Lib\site-packages\starlette\routing.py", line 735, in app
    await route.handle(scope, receive, send)
  File "C:\Users\sslinnn\Desktop\PartyFinder\.venv\Lib\site-packages\starlette\routing.py", line 288, in handle
    await self.app(scope, receive, send)
  File "C:\Users\sslinnn\Desktop\PartyFinder\.venv\Lib\site-packages\starlette\routing.py", line 76, in app
    await wrap_app_handling_exceptions(app, request)(scope, receive, send)
  File "C:\Users\sslinnn\Desktop\PartyFinder\.venv\Lib\site-packages\starlette\_exception_handler.py", line 53, in wrapped_app
    raise exc
  File "C:\Users\sslinnn\Desktop\PartyFinder\.venv\Lib\site-packages\starlette\_exception_handler.py", line 42, in wrapped_app
    await app(scope, receive, sender)
  File "C:\Users\sslinnn\Desktop\PartyFinder\.venv\Lib\site-packages\starlette\routing.py", line 73, in app
    response = await f(request)
               ^^^^^^^^^^^^^^^^
  File "C:\Users\sslinnn\Desktop\PartyFinder\.venv\Lib\site-packages\fastapi\routing.py", line 327, in app
    content = await serialize_response(
              ^^^^^^^^^^^^^^^^^^^^^^^^^
    ...<9 lines>...
    )
    ^
  File "C:\Users\sslinnn\Desktop\PartyFinder\.venv\Lib\site-packages\fastapi\routing.py", line 176, in serialize_response
    raise ResponseValidationError(
        errors=_normalize_errors(errors), body=response_content
    )
fastapi.exceptions.ResponseValidationError: 1 validation errors:
  {'type': 'bool_type', 'loc': ('response', 'email_confirmed'), 'msg': 'Input should be a valid boolean', 'input': None}

2025-02-22 23:15:35 - app - INFO - Приложение запущено
2025-02-22 23:15:37 - middleware.error_handler - INFO - Входящий запрос: POST http://localhost:8000/api/auth/register
2025-02-22 23:15:37 - api.auth.router - INFO - Запрос на регистрацию пользователя: asdwaasddaaasdsdsdwa@mail.ru
2025-02-22 23:15:37 - api.auth.auth_utils - INFO - Попытка создания пользователя с email: asdwaasddaaasdsdsdwa@mail.ru
2025-02-22 23:15:37 - api.auth.auth_utils - INFO - Пользователь успешно создан: 57
2025-02-22 23:15:37 - middleware.error_handler - INFO - Исходящий ответ: 201
2025-02-22 23:15:37 - middleware.error_handler - INFO - Входящий запрос: POST http://localhost:8000/api/auth/login
2025-02-22 23:15:37 - api.auth.router - INFO - Попытка входа пользователя: asdwaasddaaasdsdsdwa@mail.ru
2025-02-22 23:15:38 - middleware.error_handler - INFO - Исходящий ответ: 200
2025-02-22 23:15:38 - middleware.error_handler - INFO - Входящий запрос: GET http://localhost:8000/api/users/me
2025-02-22 23:15:38 - app - INFO - Запрос данных пользователя: 57
2025-02-22 23:15:38 - middleware.error_handler - ERROR - Необработанное исключение: 1 validation errors:
  {'type': 'bool_type', 'loc': ('response', 'email_confirmed'), 'msg': 'Input should be a valid boolean', 'input': None}
Traceback (most recent call last):
  File "C:\Users\sslinnn\Desktop\PartyFinder\.venv\Lib\site-packages\anyio\streams\memory.py", line 111, in receive
    return self.receive_nowait()
           ~~~~~~~~~~~~~~~~~~~^^
  File "C:\Users\sslinnn\Desktop\PartyFinder\.venv\Lib\site-packages\anyio\streams\memory.py", line 106, in receive_nowait
    raise WouldBlock
anyio.WouldBlock

During handling of the above exception, another exception occurred:

Traceback (most recent call last):
  File "C:\Users\sslinnn\Desktop\PartyFinder\.venv\Lib\site-packages\anyio\streams\memory.py", line 124, in receive
    return receiver.item
           ^^^^^^^^^^^^^
AttributeError: 'MemoryObjectItemReceiver' object has no attribute 'item'

During handling of the above exception, another exception occurred:

Traceback (most recent call last):
  File "C:\Users\sslinnn\Desktop\PartyFinder\.venv\Lib\site-packages\starlette\middleware\base.py", line 157, in call_next
    message = await recv_stream.receive()
              ^^^^^^^^^^^^^^^^^^^^^^^^^^^
  File "C:\Users\sslinnn\Desktop\PartyFinder\.venv\Lib\site-packages\anyio\streams\memory.py", line 126, in receive
    raise EndOfStream
anyio.EndOfStream

During handling of the above exception, another exception occurred:

Traceback (most recent call last):
  File "C:\Users\sslinnn\Desktop\PartyFinder\middleware\error_handler.py", line 12, in error_handler
    response = await call_next(request)
               ^^^^^^^^^^^^^^^^^^^^^^^^
  File "C:\Users\sslinnn\Desktop\PartyFinder\.venv\Lib\site-packages\starlette\middleware\base.py", line 163, in call_next
    raise app_exc
  File "C:\Users\sslinnn\Desktop\PartyFinder\.venv\Lib\site-packages\starlette\middleware\base.py", line 149, in coro
    await self.app(scope, receive_or_disconnect, send_no_error)
  File "C:\Users\sslinnn\Desktop\PartyFinder\.venv\Lib\site-packages\starlette\middleware\exceptions.py", line 62, in __call__
    await wrap_app_handling_exceptions(self.app, conn)(scope, receive, send)
  File "C:\Users\sslinnn\Desktop\PartyFinder\.venv\Lib\site-packages\starlette\_exception_handler.py", line 53, in wrapped_app
    raise exc
  File "C:\Users\sslinnn\Desktop\PartyFinder\.venv\Lib\site-packages\starlette\_exception_handler.py", line 42, in wrapped_app
    await app(scope, receive, sender)
  File "C:\Users\sslinnn\Desktop\PartyFinder\.venv\Lib\site-packages\starlette\routing.py", line 715, in __call__
    await self.middleware_stack(scope, receive, send)
  File "C:\Users\sslinnn\Desktop\PartyFinder\.venv\Lib\site-packages\starlette\routing.py", line 735, in app
    await route.handle(scope, receive, send)
  File "C:\Users\sslinnn\Desktop\PartyFinder\.venv\Lib\site-packages\starlette\routing.py", line 288, in handle
    await self.app(scope, receive, send)
  File "C:\Users\sslinnn\Desktop\PartyFinder\.venv\Lib\site-packages\starlette\routing.py", line 76, in app
    await wrap_app_handling_exceptions(app, request)(scope, receive, send)
  File "C:\Users\sslinnn\Desktop\PartyFinder\.venv\Lib\site-packages\starlette\_exception_handler.py", line 53, in wrapped_app
    raise exc
  File "C:\Users\sslinnn\Desktop\PartyFinder\.venv\Lib\site-packages\starlette\_exception_handler.py", line 42, in wrapped_app
    await app(scope, receive, sender)
  File "C:\Users\sslinnn\Desktop\PartyFinder\.venv\Lib\site-packages\starlette\routing.py", line 73, in app
    response = await f(request)
               ^^^^^^^^^^^^^^^^
  File "C:\Users\sslinnn\Desktop\PartyFinder\.venv\Lib\site-packages\fastapi\routing.py", line 327, in app
    content = await serialize_response(
              ^^^^^^^^^^^^^^^^^^^^^^^^^
    ...<9 lines>...
    )
    ^
  File "C:\Users\sslinnn\Desktop\PartyFinder\.venv\Lib\site-packages\fastapi\routing.py", line 176, in serialize_response
    raise ResponseValidationError(
        errors=_normalize_errors(errors), body=response_content
    )
fastapi.exceptions.ResponseValidationError: 1 validation errors:
  {'type': 'bool_type', 'loc': ('response', 'email_confirmed'), 'msg': 'Input should be a valid boolean', 'input': None}

2025-02-22 23:16:53 - middleware.error_handler - INFO - Входящий запрос: GET http://127.0.0.1:8000/docs
2025-02-22 23:16:53 - middleware.error_handler - INFO - Исходящий ответ: 200
2025-02-22 23:16:53 - middleware.error_handler - INFO - Входящий запрос: GET http://127.0.0.1:8000/openapi.json
2025-02-22 23:16:53 - middleware.error_handler - INFO - Исходящий ответ: 200
2025-02-22 23:17:05 - middleware.error_handler - INFO - Входящий запрос: POST http://localhost:8000/api/auth/register
2025-02-22 23:17:05 - api.auth.router - INFO - Запрос на регистрацию пользователя: asdwaasddaaasawddsdsdwa@mail.ru
2025-02-22 23:17:05 - api.auth.auth_utils - INFO - Попытка создания пользователя с email: asdwaasddaaasawddsdsdwa@mail.ru
2025-02-22 23:17:05 - api.auth.auth_utils - INFO - Пользователь успешно создан: 58
2025-02-22 23:17:05 - middleware.error_handler - INFO - Исходящий ответ: 201
2025-02-22 23:17:05 - middleware.error_handler - INFO - Входящий запрос: POST http://localhost:8000/api/auth/login
2025-02-22 23:17:05 - api.auth.router - INFO - Попытка входа пользователя: asdwaasddaaasawddsdsdwa@mail.ru
2025-02-22 23:17:05 - middleware.error_handler - INFO - Исходящий ответ: 200
2025-02-22 23:17:05 - middleware.error_handler - INFO - Входящий запрос: GET http://localhost:8000/api/users/me
2025-02-22 23:17:05 - app - INFO - Запрос данных пользователя: 58
2025-02-22 23:17:05 - middleware.error_handler - ERROR - Необработанное исключение: 1 validation errors:
  {'type': 'bool_type', 'loc': ('response', 'email_confirmed'), 'msg': 'Input should be a valid boolean', 'input': None}
Traceback (most recent call last):
  File "C:\Users\sslinnn\Desktop\PartyFinder\.venv\Lib\site-packages\anyio\streams\memory.py", line 111, in receive
    return self.receive_nowait()
           ~~~~~~~~~~~~~~~~~~~^^
  File "C:\Users\sslinnn\Desktop\PartyFinder\.venv\Lib\site-packages\anyio\streams\memory.py", line 106, in receive_nowait
    raise WouldBlock
anyio.WouldBlock

During handling of the above exception, another exception occurred:

Traceback (most recent call last):
  File "C:\Users\sslinnn\Desktop\PartyFinder\.venv\Lib\site-packages\anyio\streams\memory.py", line 124, in receive
    return receiver.item
           ^^^^^^^^^^^^^
AttributeError: 'MemoryObjectItemReceiver' object has no attribute 'item'

During handling of the above exception, another exception occurred:

Traceback (most recent call last):
  File "C:\Users\sslinnn\Desktop\PartyFinder\.venv\Lib\site-packages\starlette\middleware\base.py", line 157, in call_next
    message = await recv_stream.receive()
              ^^^^^^^^^^^^^^^^^^^^^^^^^^^
  File "C:\Users\sslinnn\Desktop\PartyFinder\.venv\Lib\site-packages\anyio\streams\memory.py", line 126, in receive
    raise EndOfStream
anyio.EndOfStream

During handling of the above exception, another exception occurred:

Traceback (most recent call last):
  File "C:\Users\sslinnn\Desktop\PartyFinder\middleware\error_handler.py", line 12, in error_handler
    response = await call_next(request)
               ^^^^^^^^^^^^^^^^^^^^^^^^
  File "C:\Users\sslinnn\Desktop\PartyFinder\.venv\Lib\site-packages\starlette\middleware\base.py", line 163, in call_next
    raise app_exc
  File "C:\Users\sslinnn\Desktop\PartyFinder\.venv\Lib\site-packages\starlette\middleware\base.py", line 149, in coro
    await self.app(scope, receive_or_disconnect, send_no_error)
  File "C:\Users\sslinnn\Desktop\PartyFinder\.venv\Lib\site-packages\starlette\middleware\exceptions.py", line 62, in __call__
    await wrap_app_handling_exceptions(self.app, conn)(scope, receive, send)
  File "C:\Users\sslinnn\Desktop\PartyFinder\.venv\Lib\site-packages\starlette\_exception_handler.py", line 53, in wrapped_app
    raise exc
  File "C:\Users\sslinnn\Desktop\PartyFinder\.venv\Lib\site-packages\starlette\_exception_handler.py", line 42, in wrapped_app
    await app(scope, receive, sender)
  File "C:\Users\sslinnn\Desktop\PartyFinder\.venv\Lib\site-packages\starlette\routing.py", line 715, in __call__
    await self.middleware_stack(scope, receive, send)
  File "C:\Users\sslinnn\Desktop\PartyFinder\.venv\Lib\site-packages\starlette\routing.py", line 735, in app
    await route.handle(scope, receive, send)
  File "C:\Users\sslinnn\Desktop\PartyFinder\.venv\Lib\site-packages\starlette\routing.py", line 288, in handle
    await self.app(scope, receive, send)
  File "C:\Users\sslinnn\Desktop\PartyFinder\.venv\Lib\site-packages\starlette\routing.py", line 76, in app
    await wrap_app_handling_exceptions(app, request)(scope, receive, send)
  File "C:\Users\sslinnn\Desktop\PartyFinder\.venv\Lib\site-packages\starlette\_exception_handler.py", line 53, in wrapped_app
    raise exc
  File "C:\Users\sslinnn\Desktop\PartyFinder\.venv\Lib\site-packages\starlette\_exception_handler.py", line 42, in wrapped_app
    await app(scope, receive, sender)
  File "C:\Users\sslinnn\Desktop\PartyFinder\.venv\Lib\site-packages\starlette\routing.py", line 73, in app
    response = await f(request)
               ^^^^^^^^^^^^^^^^
  File "C:\Users\sslinnn\Desktop\PartyFinder\.venv\Lib\site-packages\fastapi\routing.py", line 327, in app
    content = await serialize_response(
              ^^^^^^^^^^^^^^^^^^^^^^^^^
    ...<9 lines>...
    )
    ^
  File "C:\Users\sslinnn\Desktop\PartyFinder\.venv\Lib\site-packages\fastapi\routing.py", line 176, in serialize_response
    raise ResponseValidationError(
        errors=_normalize_errors(errors), body=response_content
    )
fastapi.exceptions.ResponseValidationError: 1 validation errors:
  {'type': 'bool_type', 'loc': ('response', 'email_confirmed'), 'msg': 'Input should be a valid boolean', 'input': None}

2025-02-22 23:17:31 - middleware.error_handler - INFO - Входящий запрос: POST http://localhost:8000/api/auth/register
2025-02-22 23:17:31 - api.auth.router - INFO - Запрос на регистрацию пользователя: asdwaasddaaasadwddsdsdwa@mail.ru
2025-02-22 23:17:31 - api.auth.auth_utils - INFO - Попытка создания пользователя с email: asdwaasddaaasadwddsdsdwa@mail.ru
2025-02-22 23:17:31 - api.auth.auth_utils - INFO - Пользователь успешно создан: 59
2025-02-22 23:17:31 - middleware.error_handler - INFO - Исходящий ответ: 201
2025-02-22 23:17:31 - middleware.error_handler - INFO - Входящий запрос: POST http://localhost:8000/api/auth/login
2025-02-22 23:17:31 - api.auth.router - INFO - Попытка входа пользователя: asdwaasddaaasadwddsdsdwa@mail.ru
2025-02-22 23:17:31 - middleware.error_handler - INFO - Исходящий ответ: 200
2025-02-22 23:17:31 - middleware.error_handler - INFO - Входящий запрос: GET http://localhost:8000/api/users/me
2025-02-22 23:17:31 - app - INFO - Запрос данных пользователя: 59
2025-02-22 23:17:31 - middleware.error_handler - ERROR - Необработанное исключение: 1 validation errors:
  {'type': 'bool_type', 'loc': ('response', 'email_confirmed'), 'msg': 'Input should be a valid boolean', 'input': None}
Traceback (most recent call last):
  File "C:\Users\sslinnn\Desktop\PartyFinder\.venv\Lib\site-packages\anyio\streams\memory.py", line 111, in receive
    return self.receive_nowait()
           ~~~~~~~~~~~~~~~~~~~^^
  File "C:\Users\sslinnn\Desktop\PartyFinder\.venv\Lib\site-packages\anyio\streams\memory.py", line 106, in receive_nowait
    raise WouldBlock
anyio.WouldBlock

During handling of the above exception, another exception occurred:

Traceback (most recent call last):
  File "C:\Users\sslinnn\Desktop\PartyFinder\.venv\Lib\site-packages\anyio\streams\memory.py", line 124, in receive
    return receiver.item
           ^^^^^^^^^^^^^
AttributeError: 'MemoryObjectItemReceiver' object has no attribute 'item'

During handling of the above exception, another exception occurred:

Traceback (most recent call last):
  File "C:\Users\sslinnn\Desktop\PartyFinder\.venv\Lib\site-packages\starlette\middleware\base.py", line 157, in call_next
    message = await recv_stream.receive()
              ^^^^^^^^^^^^^^^^^^^^^^^^^^^
  File "C:\Users\sslinnn\Desktop\PartyFinder\.venv\Lib\site-packages\anyio\streams\memory.py", line 126, in receive
    raise EndOfStream
anyio.EndOfStream

During handling of the above exception, another exception occurred:

Traceback (most recent call last):
  File "C:\Users\sslinnn\Desktop\PartyFinder\middleware\error_handler.py", line 12, in error_handler
    response = await call_next(request)
               ^^^^^^^^^^^^^^^^^^^^^^^^
  File "C:\Users\sslinnn\Desktop\PartyFinder\.venv\Lib\site-packages\starlette\middleware\base.py", line 163, in call_next
    raise app_exc
  File "C:\Users\sslinnn\Desktop\PartyFinder\.venv\Lib\site-packages\starlette\middleware\base.py", line 149, in coro
    await self.app(scope, receive_or_disconnect, send_no_error)
  File "C:\Users\sslinnn\Desktop\PartyFinder\.venv\Lib\site-packages\starlette\middleware\exceptions.py", line 62, in __call__
    await wrap_app_handling_exceptions(self.app, conn)(scope, receive, send)
  File "C:\Users\sslinnn\Desktop\PartyFinder\.venv\Lib\site-packages\starlette\_exception_handler.py", line 53, in wrapped_app
    raise exc
  File "C:\Users\sslinnn\Desktop\PartyFinder\.venv\Lib\site-packages\starlette\_exception_handler.py", line 42, in wrapped_app
    await app(scope, receive, sender)
  File "C:\Users\sslinnn\Desktop\PartyFinder\.venv\Lib\site-packages\starlette\routing.py", line 715, in __call__
    await self.middleware_stack(scope, receive, send)
  File "C:\Users\sslinnn\Desktop\PartyFinder\.venv\Lib\site-packages\starlette\routing.py", line 735, in app
    await route.handle(scope, receive, send)
  File "C:\Users\sslinnn\Desktop\PartyFinder\.venv\Lib\site-packages\starlette\routing.py", line 288, in handle
    await self.app(scope, receive, send)
  File "C:\Users\sslinnn\Desktop\PartyFinder\.venv\Lib\site-packages\starlette\routing.py", line 76, in app
    await wrap_app_handling_exceptions(app, request)(scope, receive, send)
  File "C:\Users\sslinnn\Desktop\PartyFinder\.venv\Lib\site-packages\starlette\_exception_handler.py", line 53, in wrapped_app
    raise exc
  File "C:\Users\sslinnn\Desktop\PartyFinder\.venv\Lib\site-packages\starlette\_exception_handler.py", line 42, in wrapped_app
    await app(scope, receive, sender)
  File "C:\Users\sslinnn\Desktop\PartyFinder\.venv\Lib\site-packages\starlette\routing.py", line 73, in app
    response = await f(request)
               ^^^^^^^^^^^^^^^^
  File "C:\Users\sslinnn\Desktop\PartyFinder\.venv\Lib\site-packages\fastapi\routing.py", line 327, in app
    content = await serialize_response(
              ^^^^^^^^^^^^^^^^^^^^^^^^^
    ...<9 lines>...
    )
    ^
  File "C:\Users\sslinnn\Desktop\PartyFinder\.venv\Lib\site-packages\fastapi\routing.py", line 176, in serialize_response
    raise ResponseValidationError(
        errors=_normalize_errors(errors), body=response_content
    )
fastapi.exceptions.ResponseValidationError: 1 validation errors:
  {'type': 'bool_type', 'loc': ('response', 'email_confirmed'), 'msg': 'Input should be a valid boolean', 'input': None}

2025-02-22 23:17:38 - app - INFO - Приложение запущено
2025-02-22 23:17:42 - middleware.error_handler - INFO - Входящий запрос: POST http://localhost:8000/api/auth/register
2025-02-22 23:17:42 - api.auth.router - INFO - Запрос на регистрацию пользователя: asdwaaswa@mail.ru
2025-02-22 23:17:42 - api.auth.auth_utils - INFO - Попытка создания пользователя с email: asdwaaswa@mail.ru
2025-02-22 23:17:42 - api.auth.auth_utils - INFO - Пользователь успешно создан: 60
2025-02-22 23:17:42 - middleware.error_handler - INFO - Исходящий ответ: 201
2025-02-22 23:17:42 - middleware.error_handler - INFO - Входящий запрос: POST http://localhost:8000/api/auth/login
2025-02-22 23:17:42 - api.auth.router - INFO - Попытка входа пользователя: asdwaaswa@mail.ru
2025-02-22 23:17:43 - middleware.error_handler - INFO - Исходящий ответ: 200
2025-02-22 23:17:43 - middleware.error_handler - INFO - Входящий запрос: GET http://localhost:8000/api/users/me
2025-02-22 23:17:43 - app - INFO - Запрос данных пользователя: 60
2025-02-22 23:17:43 - middleware.error_handler - INFO - Исходящий ответ: 200
2025-02-22 23:17:55 - middleware.error_handler - INFO - Входящий запрос: GET http://localhost:8000/api/auth/logout
2025-02-22 23:17:55 - middleware.error_handler - INFO - Исходящий ответ: 200
2025-02-22 23:18:32 - middleware.error_handler - INFO - Входящий запрос: POST http://localhost:8000/api/auth/register
2025-02-22 23:18:32 - api.auth.router - INFO - Запрос на регистрацию пользователя: asdasdasd@asd.asd
2025-02-22 23:18:32 - api.auth.auth_utils - INFO - Попытка создания пользователя с email: asdasdasd@asd.asd
2025-02-22 23:18:32 - api.auth.auth_utils - INFO - Пользователь успешно создан: 61
2025-02-22 23:18:32 - middleware.error_handler - INFO - Исходящий ответ: 201
2025-02-22 23:18:32 - middleware.error_handler - INFO - Входящий запрос: POST http://localhost:8000/api/auth/login
2025-02-22 23:18:32 - api.auth.router - INFO - Попытка входа пользователя: asdasdasd@asd.asd
2025-02-22 23:18:33 - middleware.error_handler - INFO - Исходящий ответ: 200
2025-02-22 23:18:33 - middleware.error_handler - INFO - Входящий запрос: GET http://localhost:8000/api/users/me
2025-02-22 23:18:33 - app - INFO - Запрос данных пользователя: 61
2025-02-22 23:18:33 - middleware.error_handler - INFO - Исходящий ответ: 200
2025-02-22 23:18:49 - middleware.error_handler - INFO - Входящий запрос: PATCH http://localhost:8000/api/users/update
2025-02-22 23:18:49 - middleware.error_handler - INFO - Исходящий ответ: 422
2025-02-22 23:18:49 - middleware.error_handler - INFO - Входящий запрос: GET http://localhost:8000/api/users/me
2025-02-22 23:18:49 - app - INFO - Запрос данных пользователя: 61
2025-02-22 23:18:49 - middleware.error_handler - INFO - Исходящий ответ: 200
2025-02-22 23:20:59 - app - INFO - Приложение остановлено
2025-02-22 23:21:01 - app - INFO - Приложение запущено
2025-02-22 23:21:18 - middleware.error_handler - INFO - Входящий запрос: PATCH http://localhost:8000/api/users/update
2025-02-22 23:21:18 - middleware.error_handler - INFO - Исходящий ответ: 422
2025-02-22 23:21:18 - middleware.error_handler - INFO - Входящий запрос: GET http://localhost:8000/api/users/me
2025-02-22 23:21:18 - app - INFO - Запрос данных пользователя: 61
2025-02-22 23:21:18 - middleware.error_handler - INFO - Исходящий ответ: 200
2025-02-22 23:22:30 - app - INFO - Приложение остановлено
2025-02-22 23:22:32 - app - INFO - Приложение запущено
2025-02-22 23:22:38 - middleware.error_handler - INFO - Входящий запрос: PATCH http://localhost:8000/api/users/update
2025-02-22 23:22:38 - middleware.error_handler - INFO - Исходящий ответ: 422
2025-02-22 23:22:38 - middleware.error_handler - INFO - Входящий запрос: GET http://localhost:8000/api/users/me
2025-02-22 23:22:38 - app - INFO - Запрос данных пользователя: 61
2025-02-22 23:22:38 - middleware.error_handler - INFO - Исходящий ответ: 200
2025-02-22 23:25:50 - app - INFO - Приложение остановлено
2025-02-22 23:25:54 - app - INFO - Приложение запущено
2025-02-22 23:25:59 - middleware.error_handler - INFO - Входящий запрос: PATCH http://localhost:8000/api/users/update
2025-02-22 23:26:00 - app - INFO - Запрос на обновление пользователя: 61
2025-02-22 23:26:00 - services.user_service - INFO - Попытка обновления пользователя с ID: 61
2025-02-22 23:26:00 - services.user_service - INFO - Пользователь успешно обновлен: 61
2025-02-22 23:26:00 - middleware.error_handler - INFO - Исходящий ответ: 200
2025-02-22 23:26:00 - middleware.error_handler - INFO - Входящий запрос: GET http://localhost:8000/api/users/me
2025-02-22 23:26:00 - app - INFO - Запрос данных пользователя: 61
2025-02-22 23:26:00 - middleware.error_handler - INFO - Исходящий ответ: 200
2025-02-22 23:26:24 - middleware.error_handler - INFO - Входящий запрос: PATCH http://localhost:8000/api/users/update
2025-02-22 23:26:24 - app - INFO - Запрос на обновление пользователя: 61
2025-02-22 23:26:24 - services.user_service - INFO - Попытка обновления пользователя с ID: 61
2025-02-22 23:26:24 - services.user_service - INFO - Пользователь успешно обновлен: 61
2025-02-22 23:26:24 - middleware.error_handler - INFO - Исходящий ответ: 200
2025-02-22 23:26:24 - middleware.error_handler - INFO - Входящий запрос: GET http://localhost:8000/api/users/me
2025-02-22 23:26:24 - app - INFO - Запрос данных пользователя: 61
2025-02-22 23:26:24 - middleware.error_handler - INFO - Исходящий ответ: 200
2025-02-22 23:26:45 - middleware.error_handler - INFO - Входящий запрос: GET http://localhost:8000/api/auth/logout
2025-02-22 23:26:45 - middleware.error_handler - INFO - Исходящий ответ: 200
2025-02-22 23:26:51 - middleware.error_handler - INFO - Входящий запрос: POST http://localhost:8000/api/auth/login
2025-02-22 23:26:51 - api.auth.router - INFO - Попытка входа пользователя: morison1991@mail.ru
2025-02-22 23:26:51 - middleware.error_handler - INFO - Исходящий ответ: 200
2025-02-22 23:26:51 - middleware.error_handler - INFO - Входящий запрос: GET http://localhost:8000/api/users/me
2025-02-22 23:26:51 - app - INFO - Запрос данных пользователя: 37
2025-02-22 23:26:51 - middleware.error_handler - INFO - Исходящий ответ: 200
2025-02-22 23:30:24 - app - INFO - Приложение остановлено
2025-02-22 23:30:26 - app - INFO - Приложение запущено
2025-02-22 23:30:26 - app - INFO - Приложение остановлено
2025-02-22 23:30:28 - app - INFO - Приложение запущено
2025-02-22 23:30:30 - app - INFO - Приложение запущено
2025-02-22 23:30:35 - middleware.error_handler - INFO - Входящий запрос: GET http://localhost:8000/api/auth/logout
2025-02-22 23:30:35 - middleware.error_handler - INFO - Исходящий ответ: 200
2025-02-22 23:30:51 - middleware.error_handler - INFO - Входящий запрос: POST http://localhost:8000/api/auth/register
2025-02-22 23:30:51 - api.auth.router - INFO - Запрос на регистрацию пользователя: new1@mail.ru
2025-02-22 23:30:51 - api.auth.auth_utils - INFO - Попытка создания пользователя с email: new1@mail.ru
2025-02-22 23:30:51 - api.auth.auth_utils - INFO - Пользователь успешно создан: 62
2025-02-22 23:30:51 - middleware.error_handler - INFO - Исходящий ответ: 201
2025-02-22 23:30:51 - middleware.error_handler - INFO - Входящий запрос: POST http://localhost:8000/api/auth/login
2025-02-22 23:30:51 - api.auth.router - INFO - Попытка входа пользователя: new1@mail.ru
2025-02-22 23:30:52 - middleware.error_handler - INFO - Исходящий ответ: 200
2025-02-22 23:30:52 - middleware.error_handler - INFO - Входящий запрос: GET http://localhost:8000/api/users/me
2025-02-22 23:30:52 - app - INFO - Запрос данных пользователя: 62
2025-02-22 23:30:52 - middleware.error_handler - INFO - Исходящий ответ: 200
2025-02-22 23:31:28 - middleware.error_handler - INFO - Входящий запрос: PATCH http://localhost:8000/api/users/update
2025-02-22 23:31:28 - app - INFO - Запрос на обновление пользователя: 62
2025-02-22 23:31:28 - services.user_service - INFO - Попытка обновления пользователя с ID: 62
2025-02-22 23:31:28 - services.user_service - INFO - Пользователь успешно обновлен: 62
2025-02-22 23:31:28 - middleware.error_handler - INFO - Исходящий ответ: 200
2025-02-22 23:31:28 - middleware.error_handler - INFO - Входящий запрос: GET http://localhost:8000/api/users/me
2025-02-22 23:31:28 - app - INFO - Запрос данных пользователя: 62
2025-02-22 23:31:28 - middleware.error_handler - INFO - Исходящий ответ: 200
